Workbook
Name R_HDR: '결과기록'!$1:$1
Name R_BODY: '결과기록'!$A$2:$CZ$100000
Name R_ID: INDEX(R_BODY,0,MATCH("기록ID",R_HDR,0))
Name R_LAST: MATCH(REPT("z",50),R_ID)
Name L_ID: INDEX(R_ID,1):INDEX(R_ID,R_LAST)
Name D_HDR: '측정데이터'!$1:$1
Name D_BODY: '측정데이터'!$A$2:$J$1000000
Name D_ID: INDEX(D_BODY,0,MATCH("기록ID",D_HDR,0))
Name D_LOT: INDEX(D_BODY,0,MATCH("Lot",D_HDR,0))
Name D_SEQ: INDEX(D_BODY,0,MATCH("순번",D_HDR,0))
Name D_VAL: INDEX(D_BODY,0,MATCH("값",D_HDR,0))

Sheet SPC Chart
A1: SPC Chart
A3: 기록 선택 ▶ | K3: =IF('계산'!$B$1="","(표시할 기록 없음 - 설정 안내 시트 참고)","표시 중: "&'계산'!$B$1) | Q3: =IF('계산'!$AN$3="","","저장일시 "&'계산'!$AN$3&" 작성자 "&'계산'!$AN$4&" 부분군 "&'계산'!$AN$14)
A4: 1. Specification | E4: 3. 측정Data
A5: 고객명 | C5: ='계산'!$AN$7 | E5: 공정명 | G5: ='계산'!$AN$9 | T5: 항 목 | W5: ='계산'!$AN$10 | AC5: 측정 일자 | AF5: ='계산'!$AN$12
E6: Lot Date | G6: ='계산'!$T$2&"" | H6: ='계산'!$T$3&"" | I6: ='계산'!$T$4&"" | J6: ='계산'!$T$5&"" | K6: ='계산'!$T$6&"" | L6: ='계산'!$T$7&"" | M6: ='계산'!$T$8&"" | N6: ='계산'!$T$9&"" | O6: ='계산'!$T$10&"" | P6: ='계산'!$T$11&"" | Q6: ='계산'!$T$12&"" | R6: ='계산'!$T$13&"" | S6: ='계산'!$T$14&"" | T6: ='계산'!$T$15&"" | U6: ='계산'!$T$16&"" | V6: ='계산'!$T$17&"" | W6: ='계산'!$T$18&"" | X6: ='계산'!$T$19&"" | Y6: ='계산'!$T$20&"" | Z6: ='계산'!$T$21&"" | AA6: ='계산'!$T$22&"" | AB6: ='계산'!$T$23&"" | AC6: ='계산'!$T$24&"" | AD6: ='계산'!$T$25&"" | AE6: ='계산'!$T$26&"" | AF6: ='계산'!$T$27&"" | AG6: ='계산'!$T$28&"" | AH6: ='계산'!$T$29&"" | AI6: ='계산'!$T$30&"" | AJ6: ='계산'!$T$31&""
A7: 품 명 | C7: ='계산'!$AN$8 | E7: 1 | G7: =IF(G$6="","",IFERROR(INDEX('계산'!$E$12:$E$761,MATCH("1|1",'계산'!$G$12:$G$761,0)),"")) | H7: =IF(H$6="","",IFERROR(INDEX('계산'!$E$12:$E$761,MATCH("2|1",'계산'!$G$12:$G$761,0)),"")) | I7: =IF(I$6="","",IFERROR(INDEX('계산'!$E$12:$E$761,MATCH("3|1",'계산'!$G$12:$G$761,0)),"")) | J7: =IF(J$6="","",IFERROR(INDEX('계산'!$E$12:$E$761,MATCH("4|1",'계산'!$G$12:$G$761,0)),"")) | K7: =IF(K$6="","",IFERROR(INDEX('계산'!$E$12:$E$761,MATCH("5|1",'계산'!$G$12:$G$761,0)),"")) | L7: =IF(L$6="","",IFERROR(INDEX('계산'!$E$12:$E$761,MATCH("6|1",'계산'!$G$12:$G$761,0)),"")) | M7: =IF(M$6="","",IFERROR(INDEX('계산'!$E$12:$E$761,MATCH("7|1",'계산'!$G$12:$G$761,0)),"")) | N7: =IF(N$6="","",IFERROR(INDEX('계산'!$E$12:$E$761,MATCH("8|1",'계산'!$G$12:$G$761,0)),"")) | O7: =IF(O$6="","",IFERROR(INDEX('계산'!$E$12:$E$761,MATCH("9|1",'계산'!$G$12:$G$761,0)),"")) | P7: =IF(P$6="","",IFERROR(INDEX('계산'!$E$12:$E$761,MATCH("10|1",'계산'!$G$12:$G$761,0)),"")) | Q7: =IF(Q$6="","",IFERROR(INDEX('계산'!$E$12:$E$761,MATCH("11|1",'계산'!$G$12:$G$761,0)),"")) | R7: =IF(R$6="","",IFERROR(INDEX('계산'!$E$12:$E$761,MATCH("12|1",'계산'!$G$12:$G$761,0)),"")) | S7: =IF(S$6="","",IFERROR(INDEX('계산'!$E$12:$E$761,MATCH("13|1",'계산'!$G$12:$G$761,0)),"")) | T7: =IF(T$6="","",IFERROR(INDEX('계산'!$E$12:$E$761,MATCH("14|1",'계산'!$G$12:$G$761,0)),"")) | U7: =IF(U$6="","",IFERROR(INDEX('계산'!$E$12:$E$761,MATCH("15|1",'계산'!$G$12:$G$761,0)),"")) | V7: =IF(V$6="","",IFERROR(INDEX('계산'!$E$12:$E$761,MATCH("16|1",'계산'!$G$12:$G$761,0)),"")) | W7: =IF(W$6="","",IFERROR(INDEX('계산'!$E$12:$E$761,MATCH("17|1",'계산'!$G$12:$G$761,0)),"")) | X7: =IF(X$6="","",IFERROR(INDEX('계산'!$E$12:$E$761,MATCH("18|1",'계산'!$G$12:$G$761,0)),"")) | Y7: =IF(Y$6="","",IFERROR(INDEX('계산'!$E$12:$E$761,MATCH("19|1",'계산'!$G$12:$G$761,0)),"")) | Z7: =IF(Z$6="","",IFERROR(INDEX('계산'!$E$12:$E$761,MATCH("20|1",'계산'!$G$12:$G$761,0)),"")) | AA7: =IF(AA$6="","",IFERROR(INDEX('계산'!$E$12:$E$761,MATCH("21|1",'계산'!$G$12:$G$761,0)),"")) | AB7: =IF(AB$6="","",IFERROR(INDEX('계산'!$E$12:$E$761,MATCH("22|1",'계산'!$G$12:$G$761,0)),"")) | AC7: =IF(AC$6="","",IFERROR(INDEX('계산'!$E$12:$E$761,MATCH("23|1",'계산'!$G$12:$G$761,0)),"")) | AD7: =IF(AD$6="","",IFERROR(INDEX('계산'!$E$12:$E$761,MATCH("24|1",'계산'!$G$12:$G$761,0)),"")) | AE7: =IF(AE$6="","",IFERROR(INDEX('계산'!$E$12:$E$761,MATCH("25|1",'계산'!$G$12:$G$761,0)),"")) | AF7: =IF(AF$6="","",IFERROR(INDEX('계산'!$E$12:$E$761,MATCH("26|1",'계산'!$G$12:$G$761,0)),"")) | AG7: =IF(AG$6="","",IFERROR(INDEX('계산'!$E$12:$E$761,MATCH("27|1",'계산'!$G$12:$G$761,0)),"")) | AH7: =IF(AH$6="","",IFERROR(INDEX('계산'!$E$12:$E$761,MATCH("28|1",'계산'!$G$12:$G$761,0)),"")) | AI7: =IF(AI$6="","",IFERROR(INDEX('계산'!$E$12:$E$761,MATCH("29|1",'계산'!$G$12:$G$761,0)),"")) | AJ7: =IF(AJ$6="","",IFERROR(INDEX('계산'!$E$12:$E$761,MATCH("30|1",'계산'!$G$12:$G$761,0)),""))
E8: 2 | G8: =IF(G$6="","",IFERROR(INDEX('계산'!$E$12:$E$761,MATCH("1|2",'계산'!$G$12:$G$761,0)),"")) | H8: =IF(H$6="","",IFERROR(INDEX('계산'!$E$12:$E$761,MATCH("2|2",'계산'!$G$12:$G$761,0)),"")) | I8: =IF(I$6="","",IFERROR(INDEX('계산'!$E$12:$E$761,MATCH("3|2",'계산'!$G$12:$G$761,0)),"")) | J8: =IF(J$6="","",IFERROR(INDEX('계산'!$E$12:$E$761,MATCH("4|2",'계산'!$G$12:$G$761,0)),"")) | K8: =IF(K$6="","",IFERROR(INDEX('계산'!$E$12:$E$761,MATCH("5|2",'계산'!$G$12:$G$761,0)),"")) | L8: =IF(L$6="","",IFERROR(INDEX('계산'!$E$12:$E$761,MATCH("6|2",'계산'!$G$12:$G$761,0)),"")) | M8: =IF(M$6="","",IFERROR(INDEX('계산'!$E$12:$E$761,MATCH("7|2",'계산'!$G$12:$G$761,0)),"")) | N8: =IF(N$6="","",IFERROR(INDEX('계산'!$E$12:$E$761,MATCH("8|2",'계산'!$G$12:$G$761,0)),"")) | O8: =IF(O$6="","",IFERROR(INDEX('계산'!$E$12:$E$761,MATCH("9|2",'계산'!$G$12:$G$761,0)),"")) | P8: =IF(P$6="","",IFERROR(INDEX('계산'!$E$12:$E$761,MATCH("10|2",'계산'!$G$12:$G$761,0)),"")) | Q8: =IF(Q$6="","",IFERROR(INDEX('계산'!$E$12:$E$761,MATCH("11|2",'계산'!$G$12:$G$761,0)),"")) | R8: =IF(R$6="","",IFERROR(INDEX('계산'!$E$12:$E$761,MATCH("12|2",'계산'!$G$12:$G$761,0)),"")) | S8: =IF(S$6="","",IFERROR(INDEX('계산'!$E$12:$E$761,MATCH("13|2",'계산'!$G$12:$G$761,0)),"")) | T8: =IF(T$6="","",IFERROR(INDEX('계산'!$E$12:$E$761,MATCH("14|2",'계산'!$G$12:$G$761,0)),"")) | U8: =IF(U$6="","",IFERROR(INDEX('계산'!$E$12:$E$761,MATCH("15|2",'계산'!$G$12:$G$761,0)),"")) | V8: =IF(V$6="","",IFERROR(INDEX('계산'!$E$12:$E$761,MATCH("16|2",'계산'!$G$12:$G$761,0)),"")) | W8: =IF(W$6="","",IFERROR(INDEX('계산'!$E$12:$E$761,MATCH("17|2",'계산'!$G$12:$G$761,0)),"")) | X8: =IF(X$6="","",IFERROR(INDEX('계산'!$E$12:$E$761,MATCH("18|2",'계산'!$G$12:$G$761,0)),"")) | Y8: =IF(Y$6="","",IFERROR(INDEX('계산'!$E$12:$E$761,MATCH("19|2",'계산'!$G$12:$G$761,0)),"")) | Z8: =IF(Z$6="","",IFERROR(INDEX('계산'!$E$12:$E$761,MATCH("20|2",'계산'!$G$12:$G$761,0)),"")) | AA8: =IF(AA$6="","",IFERROR(INDEX('계산'!$E$12:$E$761,MATCH("21|2",'계산'!$G$12:$G$761,0)),"")) | AB8: =IF(AB$6="","",IFERROR(INDEX('계산'!$E$12:$E$761,MATCH("22|2",'계산'!$G$12:$G$761,0)),"")) | AC8: =IF(AC$6="","",IFERROR(INDEX('계산'!$E$12:$E$761,MATCH("23|2",'계산'!$G$12:$G$761,0)),"")) | AD8: =IF(AD$6="","",IFERROR(INDEX('계산'!$E$12:$E$761,MATCH("24|2",'계산'!$G$12:$G$761,0)),"")) | AE8: =IF(AE$6="","",IFERROR(INDEX('계산'!$E$12:$E$761,MATCH("25|2",'계산'!$G$12:$G$761,0)),"")) | AF8: =IF(AF$6="","",IFERROR(INDEX('계산'!$E$12:$E$761,MATCH("26|2",'계산'!$G$12:$G$761,0)),"")) | AG8: =IF(AG$6="","",IFERROR(INDEX('계산'!$E$12:$E$761,MATCH("27|2",'계산'!$G$12:$G$761,0)),"")) | AH8: =IF(AH$6="","",IFERROR(INDEX('계산'!$E$12:$E$761,MATCH("28|2",'계산'!$G$12:$G$761,0)),"")) | AI8: =IF(AI$6="","",IFERROR(INDEX('계산'!$E$12:$E$761,MATCH("29|2",'계산'!$G$12:$G$761,0)),"")) | AJ8: =IF(AJ$6="","",IFERROR(INDEX('계산'!$E$12:$E$761,MATCH("30|2",'계산'!$G$12:$G$761,0)),""))
A9: 조 성 | C9: ='계산'!$AN$5 | E9: 3 | G9: =IF(G$6="","",IFERROR(INDEX('계산'!$E$12:$E$761,MATCH("1|3",'계산'!$G$12:$G$761,0)),"")) | H9: =IF(H$6="","",IFERROR(INDEX('계산'!$E$12:$E$761,MATCH("2|3",'계산'!$G$12:$G$761,0)),"")) | I9: =IF(I$6="","",IFERROR(INDEX('계산'!$E$12:$E$761,MATCH("3|3",'계산'!$G$12:$G$761,0)),"")) | J9: =IF(J$6="","",IFERROR(INDEX('계산'!$E$12:$E$761,MATCH("4|3",'계산'!$G$12:$G$761,0)),"")) | K9: =IF(K$6="","",IFERROR(INDEX('계산'!$E$12:$E$761,MATCH("5|3",'계산'!$G$12:$G$761,0)),"")) | L9: =IF(L$6="","",IFERROR(INDEX('계산'!$E$12:$E$761,MATCH("6|3",'계산'!$G$12:$G$761,0)),"")) | M9: =IF(M$6="","",IFERROR(INDEX('계산'!$E$12:$E$761,MATCH("7|3",'계산'!$G$12:$G$761,0)),"")) | N9: =IF(N$6="","",IFERROR(INDEX('계산'!$E$12:$E$761,MATCH("8|3",'계산'!$G$12:$G$761,0)),"")) | O9: =IF(O$6="","",IFERROR(INDEX('계산'!$E$12:$E$761,MATCH("9|3",'계산'!$G$12:$G$761,0)),"")) | P9: =IF(P$6="","",IFERROR(INDEX('계산'!$E$12:$E$761,MATCH("10|3",'계산'!$G$12:$G$761,0)),"")) | Q9: =IF(Q$6="","",IFERROR(INDEX('계산'!$E$12:$E$761,MATCH("11|3",'계산'!$G$12:$G$761,0)),"")) | R9: =IF(R$6="","",IFERROR(INDEX('계산'!$E$12:$E$761,MATCH("12|3",'계산'!$G$12:$G$761,0)),"")) | S9: =IF(S$6="","",IFERROR(INDEX('계산'!$E$12:$E$761,MATCH("13|3",'계산'!$G$12:$G$761,0)),"")) | T9: =IF(T$6="","",IFERROR(INDEX('계산'!$E$12:$E$761,MATCH("14|3",'계산'!$G$12:$G$761,0)),"")) | U9: =IF(U$6="","",IFERROR(INDEX('계산'!$E$12:$E$761,MATCH("15|3",'계산'!$G$12:$G$761,0)),"")) | V9: =IF(V$6="","",IFERROR(INDEX('계산'!$E$12:$E$761,MATCH("16|3",'계산'!$G$12:$G$761,0)),"")) | W9: =IF(W$6="","",IFERROR(INDEX('계산'!$E$12:$E$761,MATCH("17|3",'계산'!$G$12:$G$761,0)),"")) | X9: =IF(X$6="","",IFERROR(INDEX('계산'!$E$12:$E$761,MATCH("18|3",'계산'!$G$12:$G$761,0)),"")) | Y9: =IF(Y$6="","",IFERROR(INDEX('계산'!$E$12:$E$761,MATCH("19|3",'계산'!$G$12:$G$761,0)),"")) | Z9: =IF(Z$6="","",IFERROR(INDEX('계산'!$E$12:$E$761,MATCH("20|3",'계산'!$G$12:$G$761,0)),"")) | AA9: =IF(AA$6="","",IFERROR(INDEX('계산'!$E$12:$E$761,MATCH("21|3",'계산'!$G$12:$G$761,0)),"")) | AB9: =IF(AB$6="","",IFERROR(INDEX('계산'!$E$12:$E$761,MATCH("22|3",'계산'!$G$12:$G$761,0)),"")) | AC9: =IF(AC$6="","",IFERROR(INDEX('계산'!$E$12:$E$761,MATCH("23|3",'계산'!$G$12:$G$761,0)),"")) | AD9: =IF(AD$6="","",IFERROR(INDEX('계산'!$E$12:$E$761,MATCH("24|3",'계산'!$G$12:$G$761,0)),"")) | AE9: =IF(AE$6="","",IFERROR(INDEX('계산'!$E$12:$E$761,MATCH("25|3",'계산'!$G$12:$G$761,0)),"")) | AF9: =IF(AF$6="","",IFERROR(INDEX('계산'!$E$12:$E$761,MATCH("26|3",'계산'!$G$12:$G$761,0)),"")) | AG9: =IF(AG$6="","",IFERROR(INDEX('계산'!$E$12:$E$761,MATCH("27|3",'계산'!$G$12:$G$761,0)),"")) | AH9: =IF(AH$6="","",IFERROR(INDEX('계산'!$E$12:$E$761,MATCH("28|3",'계산'!$G$12:$G$761,0)),"")) | AI9: =IF(AI$6="","",IFERROR(INDEX('계산'!$E$12:$E$761,MATCH("29|3",'계산'!$G$12:$G$761,0)),"")) | AJ9: =IF(AJ$6="","",IFERROR(INDEX('계산'!$E$12:$E$761,MATCH("30|3",'계산'!$G$12:$G$761,0)),""))
E10: 4 | G10: =IF(G$6="","",IFERROR(INDEX('계산'!$E$12:$E$761,MATCH("1|4",'계산'!$G$12:$G$761,0)),"")) | H10: =IF(H$6="","",IFERROR(INDEX('계산'!$E$12:$E$761,MATCH("2|4",'계산'!$G$12:$G$761,0)),"")) | I10: =IF(I$6="","",IFERROR(INDEX('계산'!$E$12:$E$761,MATCH("3|4",'계산'!$G$12:$G$761,0)),"")) | J10: =IF(J$6="","",IFERROR(INDEX('계산'!$E$12:$E$761,MATCH("4|4",'계산'!$G$12:$G$761,0)),"")) | K10: =IF(K$6="","",IFERROR(INDEX('계산'!$E$12:$E$761,MATCH("5|4",'계산'!$G$12:$G$761,0)),"")) | L10: =IF(L$6="","",IFERROR(INDEX('계산'!$E$12:$E$761,MATCH("6|4",'계산'!$G$12:$G$761,0)),"")) | M10: =IF(M$6="","",IFERROR(INDEX('계산'!$E$12:$E$761,MATCH("7|4",'계산'!$G$12:$G$761,0)),"")) | N10: =IF(N$6="","",IFERROR(INDEX('계산'!$E$12:$E$761,MATCH("8|4",'계산'!$G$12:$G$761,0)),"")) | O10: =IF(O$6="","",IFERROR(INDEX('계산'!$E$12:$E$761,MATCH("9|4",'계산'!$G$12:$G$761,0)),"")) | P10: =IF(P$6="","",IFERROR(INDEX('계산'!$E$12:$E$761,MATCH("10|4",'계산'!$G$12:$G$761,0)),"")) | Q10: =IF(Q$6="","",IFERROR(INDEX('계산'!$E$12:$E$761,MATCH("11|4",'계산'!$G$12:$G$761,0)),"")) | R10: =IF(R$6="","",IFERROR(INDEX('계산'!$E$12:$E$761,MATCH("12|4",'계산'!$G$12:$G$761,0)),"")) | S10: =IF(S$6="","",IFERROR(INDEX('계산'!$E$12:$E$761,MATCH("13|4",'계산'!$G$12:$G$761,0)),"")) | T10: =IF(T$6="","",IFERROR(INDEX('계산'!$E$12:$E$761,MATCH("14|4",'계산'!$G$12:$G$761,0)),"")) | U10: =IF(U$6="","",IFERROR(INDEX('계산'!$E$12:$E$761,MATCH("15|4",'계산'!$G$12:$G$761,0)),"")) | V10: =IF(V$6="","",IFERROR(INDEX('계산'!$E$12:$E$761,MATCH("16|4",'계산'!$G$12:$G$761,0)),"")) | W10: =IF(W$6="","",IFERROR(INDEX('계산'!$E$12:$E$761,MATCH("17|4",'계산'!$G$12:$G$761,0)),"")) | X10: =IF(X$6="","",IFERROR(INDEX('계산'!$E$12:$E$761,MATCH("18|4",'계산'!$G$12:$G$761,0)),"")) | Y10: =IF(Y$6="","",IFERROR(INDEX('계산'!$E$12:$E$761,MATCH("19|4",'계산'!$G$12:$G$761,0)),"")) | Z10: =IF(Z$6="","",IFERROR(INDEX('계산'!$E$12:$E$761,MATCH("20|4",'계산'!$G$12:$G$761,0)),"")) | AA10: =IF(AA$6="","",IFERROR(INDEX('계산'!$E$12:$E$761,MATCH("21|4",'계산'!$G$12:$G$761,0)),"")) | AB10: =IF(AB$6="","",IFERROR(INDEX('계산'!$E$12:$E$761,MATCH("22|4",'계산'!$G$12:$G$761,0)),"")) | AC10: =IF(AC$6="","",IFERROR(INDEX('계산'!$E$12:$E$761,MATCH("23|4",'계산'!$G$12:$G$761,0)),"")) | AD10: =IF(AD$6="","",IFERROR(INDEX('계산'!$E$12:$E$761,MATCH("24|4",'계산'!$G$12:$G$761,0)),"")) | AE10: =IF(AE$6="","",IFERROR(INDEX('계산'!$E$12:$E$761,MATCH("25|4",'계산'!$G$12:$G$761,0)),"")) | AF10: =IF(AF$6="","",IFERROR(INDEX('계산'!$E$12:$E$761,MATCH("26|4",'계산'!$G$12:$G$761,0)),"")) | AG10: =IF(AG$6="","",IFERROR(INDEX('계산'!$E$12:$E$761,MATCH("27|4",'계산'!$G$12:$G$761,0)),"")) | AH10: =IF(AH$6="","",IFERROR(INDEX('계산'!$E$12:$E$761,MATCH("28|4",'계산'!$G$12:$G$761,0)),"")) | AI10: =IF(AI$6="","",IFERROR(INDEX('계산'!$E$12:$E$761,MATCH("29|4",'계산'!$G$12:$G$761,0)),"")) | AJ10: =IF(AJ$6="","",IFERROR(INDEX('계산'!$E$12:$E$761,MATCH("30|4",'계산'!$G$12:$G$761,0)),""))
A11: 품번 customer | C11: - | E11: 5 | G11: =IF(G$6="","",IFERROR(INDEX('계산'!$E$12:$E$761,MATCH("1|5",'계산'!$G$12:$G$761,0)),"")) | H11: =IF(H$6="","",IFERROR(INDEX('계산'!$E$12:$E$761,MATCH("2|5",'계산'!$G$12:$G$761,0)),"")) | I11: =IF(I$6="","",IFERROR(INDEX('계산'!$E$12:$E$761,MATCH("3|5",'계산'!$G$12:$G$761,0)),"")) | J11: =IF(J$6="","",IFERROR(INDEX('계산'!$E$12:$E$761,MATCH("4|5",'계산'!$G$12:$G$761,0)),"")) | K11: =IF(K$6="","",IFERROR(INDEX('계산'!$E$12:$E$761,MATCH("5|5",'계산'!$G$12:$G$761,0)),"")) | L11: =IF(L$6="","",IFERROR(INDEX('계산'!$E$12:$E$761,MATCH("6|5",'계산'!$G$12:$G$761,0)),"")) | M11: =IF(M$6="","",IFERROR(INDEX('계산'!$E$12:$E$761,MATCH("7|5",'계산'!$G$12:$G$761,0)),"")) | N11: =IF(N$6="","",IFERROR(INDEX('계산'!$E$12:$E$761,MATCH("8|5",'계산'!$G$12:$G$761,0)),"")) | O11: =IF(O$6="","",IFERROR(INDEX('계산'!$E$12:$E$761,MATCH("9|5",'계산'!$G$12:$G$761,0)),"")) | P11: =IF(P$6="","",IFERROR(INDEX('계산'!$E$12:$E$761,MATCH("10|5",'계산'!$G$12:$G$761,0)),"")) | Q11: =IF(Q$6="","",IFERROR(INDEX('계산'!$E$12:$E$761,MATCH("11|5",'계산'!$G$12:$G$761,0)),"")) | R11: =IF(R$6="","",IFERROR(INDEX('계산'!$E$12:$E$761,MATCH("12|5",'계산'!$G$12:$G$761,0)),"")) | S11: =IF(S$6="","",IFERROR(INDEX('계산'!$E$12:$E$761,MATCH("13|5",'계산'!$G$12:$G$761,0)),"")) | T11: =IF(T$6="","",IFERROR(INDEX('계산'!$E$12:$E$761,MATCH("14|5",'계산'!$G$12:$G$761,0)),"")) | U11: =IF(U$6="","",IFERROR(INDEX('계산'!$E$12:$E$761,MATCH("15|5",'계산'!$G$12:$G$761,0)),"")) | V11: =IF(V$6="","",IFERROR(INDEX('계산'!$E$12:$E$761,MATCH("16|5",'계산'!$G$12:$G$761,0)),"")) | W11: =IF(W$6="","",IFERROR(INDEX('계산'!$E$12:$E$761,MATCH("17|5",'계산'!$G$12:$G$761,0)),"")) | X11: =IF(X$6="","",IFERROR(INDEX('계산'!$E$12:$E$761,MATCH("18|5",'계산'!$G$12:$G$761,0)),"")) | Y11: =IF(Y$6="","",IFERROR(INDEX('계산'!$E$12:$E$761,MATCH("19|5",'계산'!$G$12:$G$761,0)),"")) | Z11: =IF(Z$6="","",IFERROR(INDEX('계산'!$E$12:$E$761,MATCH("20|5",'계산'!$G$12:$G$761,0)),"")) | AA11: =IF(AA$6="","",IFERROR(INDEX('계산'!$E$12:$E$761,MATCH("21|5",'계산'!$G$12:$G$761,0)),"")) | AB11: =IF(AB$6="","",IFERROR(INDEX('계산'!$E$12:$E$761,MATCH("22|5",'계산'!$G$12:$G$761,0)),"")) | AC11: =IF(AC$6="","",IFERROR(INDEX('계산'!$E$12:$E$761,MATCH("23|5",'계산'!$G$12:$G$761,0)),"")) | AD11: =IF(AD$6="","",IFERROR(INDEX('계산'!$E$12:$E$761,MATCH("24|5",'계산'!$G$12:$G$761,0)),"")) | AE11: =IF(AE$6="","",IFERROR(INDEX('계산'!$E$12:$E$761,MATCH("25|5",'계산'!$G$12:$G$761,0)),"")) | AF11: =IF(AF$6="","",IFERROR(INDEX('계산'!$E$12:$E$761,MATCH("26|5",'계산'!$G$12:$G$761,0)),"")) | AG11: =IF(AG$6="","",IFERROR(INDEX('계산'!$E$12:$E$761,MATCH("27|5",'계산'!$G$12:$G$761,0)),"")) | AH11: =IF(AH$6="","",IFERROR(INDEX('계산'!$E$12:$E$761,MATCH("28|5",'계산'!$G$12:$G$761,0)),"")) | AI11: =IF(AI$6="","",IFERROR(INDEX('계산'!$E$12:$E$761,MATCH("29|5",'계산'!$G$12:$G$761,0)),"")) | AJ11: =IF(AJ$6="","",IFERROR(INDEX('계산'!$E$12:$E$761,MATCH("30|5",'계산'!$G$12:$G$761,0)),""))
E12: 6 | G12: =IF(G$6="","",IFERROR(INDEX('계산'!$E$12:$E$761,MATCH("1|6",'계산'!$G$12:$G$761,0)),"")) | H12: =IF(H$6="","",IFERROR(INDEX('계산'!$E$12:$E$761,MATCH("2|6",'계산'!$G$12:$G$761,0)),"")) | I12: =IF(I$6="","",IFERROR(INDEX('계산'!$E$12:$E$761,MATCH("3|6",'계산'!$G$12:$G$761,0)),"")) | J12: =IF(J$6="","",IFERROR(INDEX('계산'!$E$12:$E$761,MATCH("4|6",'계산'!$G$12:$G$761,0)),"")) | K12: =IF(K$6="","",IFERROR(INDEX('계산'!$E$12:$E$761,MATCH("5|6",'계산'!$G$12:$G$761,0)),"")) | L12: =IF(L$6="","",IFERROR(INDEX('계산'!$E$12:$E$761,MATCH("6|6",'계산'!$G$12:$G$761,0)),"")) | M12: =IF(M$6="","",IFERROR(INDEX('계산'!$E$12:$E$761,MATCH("7|6",'계산'!$G$12:$G$761,0)),"")) | N12: =IF(N$6="","",IFERROR(INDEX('계산'!$E$12:$E$761,MATCH("8|6",'계산'!$G$12:$G$761,0)),"")) | O12: =IF(O$6="","",IFERROR(INDEX('계산'!$E$12:$E$761,MATCH("9|6",'계산'!$G$12:$G$761,0)),"")) | P12: =IF(P$6="","",IFERROR(INDEX('계산'!$E$12:$E$761,MATCH("10|6",'계산'!$G$12:$G$761,0)),"")) | Q12: =IF(Q$6="","",IFERROR(INDEX('계산'!$E$12:$E$761,MATCH("11|6",'계산'!$G$12:$G$761,0)),"")) | R12: =IF(R$6="","",IFERROR(INDEX('계산'!$E$12:$E$761,MATCH("12|6",'계산'!$G$12:$G$761,0)),"")) | S12: =IF(S$6="","",IFERROR(INDEX('계산'!$E$12:$E$761,MATCH("13|6",'계산'!$G$12:$G$761,0)),"")) | T12: =IF(T$6="","",IFERROR(INDEX('계산'!$E$12:$E$761,MATCH("14|6",'계산'!$G$12:$G$761,0)),"")) | U12: =IF(U$6="","",IFERROR(INDEX('계산'!$E$12:$E$761,MATCH("15|6",'계산'!$G$12:$G$761,0)),"")) | V12: =IF(V$6="","",IFERROR(INDEX('계산'!$E$12:$E$761,MATCH("16|6",'계산'!$G$12:$G$761,0)),"")) | W12: =IF(W$6="","",IFERROR(INDEX('계산'!$E$12:$E$761,MATCH("17|6",'계산'!$G$12:$G$761,0)),"")) | X12: =IF(X$6="","",IFERROR(INDEX('계산'!$E$12:$E$761,MATCH("18|6",'계산'!$G$12:$G$761,0)),"")) | Y12: =IF(Y$6="","",IFERROR(INDEX('계산'!$E$12:$E$761,MATCH("19|6",'계산'!$G$12:$G$761,0)),"")) | Z12: =IF(Z$6="","",IFERROR(INDEX('계산'!$E$12:$E$761,MATCH("20|6",'계산'!$G$12:$G$761,0)),"")) | AA12: =IF(AA$6="","",IFERROR(INDEX('계산'!$E$12:$E$761,MATCH("21|6",'계산'!$G$12:$G$761,0)),"")) | AB12: =IF(AB$6="","",IFERROR(INDEX('계산'!$E$12:$E$761,MATCH("22|6",'계산'!$G$12:$G$761,0)),"")) | AC12: =IF(AC$6="","",IFERROR(INDEX('계산'!$E$12:$E$761,MATCH("23|6",'계산'!$G$12:$G$761,0)),"")) | AD12: =IF(AD$6="","",IFERROR(INDEX('계산'!$E$12:$E$761,MATCH("24|6",'계산'!$G$12:$G$761,0)),"")) | AE12: =IF(AE$6="","",IFERROR(INDEX('계산'!$E$12:$E$761,MATCH("25|6",'계산'!$G$12:$G$761,0)),"")) | AF12: =IF(AF$6="","",IFERROR(INDEX('계산'!$E$12:$E$761,MATCH("26|6",'계산'!$G$12:$G$761,0)),"")) | AG12: =IF(AG$6="","",IFERROR(INDEX('계산'!$E$12:$E$761,MATCH("27|6",'계산'!$G$12:$G$761,0)),"")) | AH12: =IF(AH$6="","",IFERROR(INDEX('계산'!$E$12:$E$761,MATCH("28|6",'계산'!$G$12:$G$761,0)),"")) | AI12: =IF(AI$6="","",IFERROR(INDEX('계산'!$E$12:$E$761,MATCH("29|6",'계산'!$G$12:$G$761,0)),"")) | AJ12: =IF(AJ$6="","",IFERROR(INDEX('계산'!$E$12:$E$761,MATCH("30|6",'계산'!$G$12:$G$761,0)),""))
A13: 품번 Amphenol | C13: - | E13: 7 | G13: =IF(G$6="","",IFERROR(INDEX('계산'!$E$12:$E$761,MATCH("1|7",'계산'!$G$12:$G$761,0)),"")) | H13: =IF(H$6="","",IFERROR(INDEX('계산'!$E$12:$E$761,MATCH("2|7",'계산'!$G$12:$G$761,0)),"")) | I13: =IF(I$6="","",IFERROR(INDEX('계산'!$E$12:$E$761,MATCH("3|7",'계산'!$G$12:$G$761,0)),"")) | J13: =IF(J$6="","",IFERROR(INDEX('계산'!$E$12:$E$761,MATCH("4|7",'계산'!$G$12:$G$761,0)),"")) | K13: =IF(K$6="","",IFERROR(INDEX('계산'!$E$12:$E$761,MATCH("5|7",'계산'!$G$12:$G$761,0)),"")) | L13: =IF(L$6="","",IFERROR(INDEX('계산'!$E$12:$E$761,MATCH("6|7",'계산'!$G$12:$G$761,0)),"")) | M13: =IF(M$6="","",IFERROR(INDEX('계산'!$E$12:$E$761,MATCH("7|7",'계산'!$G$12:$G$761,0)),"")) | N13: =IF(N$6="","",IFERROR(INDEX('계산'!$E$12:$E$761,MATCH("8|7",'계산'!$G$12:$G$761,0)),"")) | O13: =IF(O$6="","",IFERROR(INDEX('계산'!$E$12:$E$761,MATCH("9|7",'계산'!$G$12:$G$761,0)),"")) | P13: =IF(P$6="","",IFERROR(INDEX('계산'!$E$12:$E$761,MATCH("10|7",'계산'!$G$12:$G$761,0)),"")) | Q13: =IF(Q$6="","",IFERROR(INDEX('계산'!$E$12:$E$761,MATCH("11|7",'계산'!$G$12:$G$761,0)),"")) | R13: =IF(R$6="","",IFERROR(INDEX('계산'!$E$12:$E$761,MATCH("12|7",'계산'!$G$12:$G$761,0)),"")) | S13: =IF(S$6="","",IFERROR(INDEX('계산'!$E$12:$E$761,MATCH("13|7",'계산'!$G$12:$G$761,0)),"")) | T13: =IF(T$6="","",IFERROR(INDEX('계산'!$E$12:$E$761,MATCH("14|7",'계산'!$G$12:$G$761,0)),"")) | U13: =IF(U$6="","",IFERROR(INDEX('계산'!$E$12:$E$761,MATCH("15|7",'계산'!$G$12:$G$761,0)),"")) | V13: =IF(V$6="","",IFERROR(INDEX('계산'!$E$12:$E$761,MATCH("16|7",'계산'!$G$12:$G$761,0)),"")) | W13: =IF(W$6="","",IFERROR(INDEX('계산'!$E$12:$E$761,MATCH("17|7",'계산'!$G$12:$G$761,0)),"")) | X13: =IF(X$6="","",IFERROR(INDEX('계산'!$E$12:$E$761,MATCH("18|7",'계산'!$G$12:$G$761,0)),"")) | Y13: =IF(Y$6="","",IFERROR(INDEX('계산'!$E$12:$E$761,MATCH("19|7",'계산'!$G$12:$G$761,0)),"")) | Z13: =IF(Z$6="","",IFERROR(INDEX('계산'!$E$12:$E$761,MATCH("20|7",'계산'!$G$12:$G$761,0)),"")) | AA13: =IF(AA$6="","",IFERROR(INDEX('계산'!$E$12:$E$761,MATCH("21|7",'계산'!$G$12:$G$761,0)),"")) | AB13: =IF(AB$6="","",IFERROR(INDEX('계산'!$E$12:$E$761,MATCH("22|7",'계산'!$G$12:$G$761,0)),"")) | AC13: =IF(AC$6="","",IFERROR(INDEX('계산'!$E$12:$E$761,MATCH("23|7",'계산'!$G$12:$G$761,0)),"")) | AD13: =IF(AD$6="","",IFERROR(INDEX('계산'!$E$12:$E$761,MATCH("24|7",'계산'!$G$12:$G$761,0)),"")) | AE13: =IF(AE$6="","",IFERROR(INDEX('계산'!$E$12:$E$761,MATCH("25|7",'계산'!$G$12:$G$761,0)),"")) | AF13: =IF(AF$6="","",IFERROR(INDEX('계산'!$E$12:$E$761,MATCH("26|7",'계산'!$G$12:$G$761,0)),"")) | AG13: =IF(AG$6="","",IFERROR(INDEX('계산'!$E$12:$E$761,MATCH("27|7",'계산'!$G$12:$G$761,0)),"")) | AH13: =IF(AH$6="","",IFERROR(INDEX('계산'!$E$12:$E$761,MATCH("28|7",'계산'!$G$12:$G$761,0)),"")) | AI13: =IF(AI$6="","",IFERROR(INDEX('계산'!$E$12:$E$761,MATCH("29|7",'계산'!$G$12:$G$761,0)),"")) | AJ13: =IF(AJ$6="","",IFERROR(INDEX('계산'!$E$12:$E$761,MATCH("30|7",'계산'!$G$12:$G$761,0)),""))
E14: 8 | G14: =IF(G$6="","",IFERROR(INDEX('계산'!$E$12:$E$761,MATCH("1|8",'계산'!$G$12:$G$761,0)),"")) | H14: =IF(H$6="","",IFERROR(INDEX('계산'!$E$12:$E$761,MATCH("2|8",'계산'!$G$12:$G$761,0)),"")) | I14: =IF(I$6="","",IFERROR(INDEX('계산'!$E$12:$E$761,MATCH("3|8",'계산'!$G$12:$G$761,0)),"")) | J14: =IF(J$6="","",IFERROR(INDEX('계산'!$E$12:$E$761,MATCH("4|8",'계산'!$G$12:$G$761,0)),"")) | K14: =IF(K$6="","",IFERROR(INDEX('계산'!$E$12:$E$761,MATCH("5|8",'계산'!$G$12:$G$761,0)),"")) | L14: =IF(L$6="","",IFERROR(INDEX('계산'!$E$12:$E$761,MATCH("6|8",'계산'!$G$12:$G$761,0)),"")) | M14: =IF(M$6="","",IFERROR(INDEX('계산'!$E$12:$E$761,MATCH("7|8",'계산'!$G$12:$G$761,0)),"")) | N14: =IF(N$6="","",IFERROR(INDEX('계산'!$E$12:$E$761,MATCH("8|8",'계산'!$G$12:$G$761,0)),"")) | O14: =IF(O$6="","",IFERROR(INDEX('계산'!$E$12:$E$761,MATCH("9|8",'계산'!$G$12:$G$761,0)),"")) | P14: =IF(P$6="","",IFERROR(INDEX('계산'!$E$12:$E$761,MATCH("10|8",'계산'!$G$12:$G$761,0)),"")) | Q14: =IF(Q$6="","",IFERROR(INDEX('계산'!$E$12:$E$761,MATCH("11|8",'계산'!$G$12:$G$761,0)),"")) | R14: =IF(R$6="","",IFERROR(INDEX('계산'!$E$12:$E$761,MATCH("12|8",'계산'!$G$12:$G$761,0)),"")) | S14: =IF(S$6="","",IFERROR(INDEX('계산'!$E$12:$E$761,MATCH("13|8",'계산'!$G$12:$G$761,0)),"")) | T14: =IF(T$6="","",IFERROR(INDEX('계산'!$E$12:$E$761,MATCH("14|8",'계산'!$G$12:$G$761,0)),"")) | U14: =IF(U$6="","",IFERROR(INDEX('계산'!$E$12:$E$761,MATCH("15|8",'계산'!$G$12:$G$761,0)),"")) | V14: =IF(V$6="","",IFERROR(INDEX('계산'!$E$12:$E$761,MATCH("16|8",'계산'!$G$12:$G$761,0)),"")) | W14: =IF(W$6="","",IFERROR(INDEX('계산'!$E$12:$E$761,MATCH("17|8",'계산'!$G$12:$G$761,0)),"")) | X14: =IF(X$6="","",IFERROR(INDEX('계산'!$E$12:$E$761,MATCH("18|8",'계산'!$G$12:$G$761,0)),"")) | Y14: =IF(Y$6="","",IFERROR(INDEX('계산'!$E$12:$E$761,MATCH("19|8",'계산'!$G$12:$G$761,0)),"")) | Z14: =IF(Z$6="","",IFERROR(INDEX('계산'!$E$12:$E$761,MATCH("20|8",'계산'!$G$12:$G$761,0)),"")) | AA14: =IF(AA$6="","",IFERROR(INDEX('계산'!$E$12:$E$761,MATCH("21|8",'계산'!$G$12:$G$761,0)),"")) | AB14: =IF(AB$6="","",IFERROR(INDEX('계산'!$E$12:$E$761,MATCH("22|8",'계산'!$G$12:$G$761,0)),"")) | AC14: =IF(AC$6="","",IFERROR(INDEX('계산'!$E$12:$E$761,MATCH("23|8",'계산'!$G$12:$G$761,0)),"")) | AD14: =IF(AD$6="","",IFERROR(INDEX('계산'!$E$12:$E$761,MATCH("24|8",'계산'!$G$12:$G$761,0)),"")) | AE14: =IF(AE$6="","",IFERROR(INDEX('계산'!$E$12:$E$761,MATCH("25|8",'계산'!$G$12:$G$761,0)),"")) | AF14: =IF(AF$6="","",IFERROR(INDEX('계산'!$E$12:$E$761,MATCH("26|8",'계산'!$G$12:$G$761,0)),"")) | AG14: =IF(AG$6="","",IFERROR(INDEX('계산'!$E$12:$E$761,MATCH("27|8",'계산'!$G$12:$G$761,0)),"")) | AH14: =IF(AH$6="","",IFERROR(INDEX('계산'!$E$12:$E$761,MATCH("28|8",'계산'!$G$12:$G$761,0)),"")) | AI14: =IF(AI$6="","",IFERROR(INDEX('계산'!$E$12:$E$761,MATCH("29|8",'계산'!$G$12:$G$761,0)),"")) | AJ14: =IF(AJ$6="","",IFERROR(INDEX('계산'!$E$12:$E$761,MATCH("30|8",'계산'!$G$12:$G$761,0)),""))
A15: 차 종 | E15: 9 | G15: =IF(G$6="","",IFERROR(INDEX('계산'!$E$12:$E$761,MATCH("1|9",'계산'!$G$12:$G$761,0)),"")) | H15: =IF(H$6="","",IFERROR(INDEX('계산'!$E$12:$E$761,MATCH("2|9",'계산'!$G$12:$G$761,0)),"")) | I15: =IF(I$6="","",IFERROR(INDEX('계산'!$E$12:$E$761,MATCH("3|9",'계산'!$G$12:$G$761,0)),"")) | J15: =IF(J$6="","",IFERROR(INDEX('계산'!$E$12:$E$761,MATCH("4|9",'계산'!$G$12:$G$761,0)),"")) | K15: =IF(K$6="","",IFERROR(INDEX('계산'!$E$12:$E$761,MATCH("5|9",'계산'!$G$12:$G$761,0)),"")) | L15: =IF(L$6="","",IFERROR(INDEX('계산'!$E$12:$E$761,MATCH("6|9",'계산'!$G$12:$G$761,0)),"")) | M15: =IF(M$6="","",IFERROR(INDEX('계산'!$E$12:$E$761,MATCH("7|9",'계산'!$G$12:$G$761,0)),"")) | N15: =IF(N$6="","",IFERROR(INDEX('계산'!$E$12:$E$761,MATCH("8|9",'계산'!$G$12:$G$761,0)),"")) | O15: =IF(O$6="","",IFERROR(INDEX('계산'!$E$12:$E$761,MATCH("9|9",'계산'!$G$12:$G$761,0)),"")) | P15: =IF(P$6="","",IFERROR(INDEX('계산'!$E$12:$E$761,MATCH("10|9",'계산'!$G$12:$G$761,0)),"")) | Q15: =IF(Q$6="","",IFERROR(INDEX('계산'!$E$12:$E$761,MATCH("11|9",'계산'!$G$12:$G$761,0)),"")) | R15: =IF(R$6="","",IFERROR(INDEX('계산'!$E$12:$E$761,MATCH("12|9",'계산'!$G$12:$G$761,0)),"")) | S15: =IF(S$6="","",IFERROR(INDEX('계산'!$E$12:$E$761,MATCH("13|9",'계산'!$G$12:$G$761,0)),"")) | T15: =IF(T$6="","",IFERROR(INDEX('계산'!$E$12:$E$761,MATCH("14|9",'계산'!$G$12:$G$761,0)),"")) | U15: =IF(U$6="","",IFERROR(INDEX('계산'!$E$12:$E$761,MATCH("15|9",'계산'!$G$12:$G$761,0)),"")) | V15: =IF(V$6="","",IFERROR(INDEX('계산'!$E$12:$E$761,MATCH("16|9",'계산'!$G$12:$G$761,0)),"")) | W15: =IF(W$6="","",IFERROR(INDEX('계산'!$E$12:$E$761,MATCH("17|9",'계산'!$G$12:$G$761,0)),"")) | X15: =IF(X$6="","",IFERROR(INDEX('계산'!$E$12:$E$761,MATCH("18|9",'계산'!$G$12:$G$761,0)),"")) | Y15: =IF(Y$6="","",IFERROR(INDEX('계산'!$E$12:$E$761,MATCH("19|9",'계산'!$G$12:$G$761,0)),"")) | Z15: =IF(Z$6="","",IFERROR(INDEX('계산'!$E$12:$E$761,MATCH("20|9",'계산'!$G$12:$G$761,0)),"")) | AA15: =IF(AA$6="","",IFERROR(INDEX('계산'!$E$12:$E$761,MATCH("21|9",'계산'!$G$12:$G$761,0)),"")) | AB15: =IF(AB$6="","",IFERROR(INDEX('계산'!$E$12:$E$761,MATCH("22|9",'계산'!$G$12:$G$761,0)),"")) | AC15: =IF(AC$6="","",IFERROR(INDEX('계산'!$E$12:$E$761,MATCH("23|9",'계산'!$G$12:$G$761,0)),"")) | AD15: =IF(AD$6="","",IFERROR(INDEX('계산'!$E$12:$E$761,MATCH("24|9",'계산'!$G$12:$G$761,0)),"")) | AE15: =IF(AE$6="","",IFERROR(INDEX('계산'!$E$12:$E$761,MATCH("25|9",'계산'!$G$12:$G$761,0)),"")) | AF15: =IF(AF$6="","",IFERROR(INDEX('계산'!$E$12:$E$761,MATCH("26|9",'계산'!$G$12:$G$761,0)),"")) | AG15: =IF(AG$6="","",IFERROR(INDEX('계산'!$E$12:$E$761,MATCH("27|9",'계산'!$G$12:$G$761,0)),"")) | AH15: =IF(AH$6="","",IFERROR(INDEX('계산'!$E$12:$E$761,MATCH("28|9",'계산'!$G$12:$G$761,0)),"")) | AI15: =IF(AI$6="","",IFERROR(INDEX('계산'!$E$12:$E$761,MATCH("29|9",'계산'!$G$12:$G$761,0)),"")) | AJ15: =IF(AJ$6="","",IFERROR(INDEX('계산'!$E$12:$E$761,MATCH("30|9",'계산'!$G$12:$G$761,0)),""))
E16: 10 | G16: =IF(G$6="","",IFERROR(INDEX('계산'!$E$12:$E$761,MATCH("1|10",'계산'!$G$12:$G$761,0)),"")) | H16: =IF(H$6="","",IFERROR(INDEX('계산'!$E$12:$E$761,MATCH("2|10",'계산'!$G$12:$G$761,0)),"")) | I16: =IF(I$6="","",IFERROR(INDEX('계산'!$E$12:$E$761,MATCH("3|10",'계산'!$G$12:$G$761,0)),"")) | J16: =IF(J$6="","",IFERROR(INDEX('계산'!$E$12:$E$761,MATCH("4|10",'계산'!$G$12:$G$761,0)),"")) | K16: =IF(K$6="","",IFERROR(INDEX('계산'!$E$12:$E$761,MATCH("5|10",'계산'!$G$12:$G$761,0)),"")) | L16: =IF(L$6="","",IFERROR(INDEX('계산'!$E$12:$E$761,MATCH("6|10",'계산'!$G$12:$G$761,0)),"")) | M16: =IF(M$6="","",IFERROR(INDEX('계산'!$E$12:$E$761,MATCH("7|10",'계산'!$G$12:$G$761,0)),"")) | N16: =IF(N$6="","",IFERROR(INDEX('계산'!$E$12:$E$761,MATCH("8|10",'계산'!$G$12:$G$761,0)),"")) | O16: =IF(O$6="","",IFERROR(INDEX('계산'!$E$12:$E$761,MATCH("9|10",'계산'!$G$12:$G$761,0)),"")) | P16: =IF(P$6="","",IFERROR(INDEX('계산'!$E$12:$E$761,MATCH("10|10",'계산'!$G$12:$G$761,0)),"")) | Q16: =IF(Q$6="","",IFERROR(INDEX('계산'!$E$12:$E$761,MATCH("11|10",'계산'!$G$12:$G$761,0)),"")) | R16: =IF(R$6="","",IFERROR(INDEX('계산'!$E$12:$E$761,MATCH("12|10",'계산'!$G$12:$G$761,0)),"")) | S16: =IF(S$6="","",IFERROR(INDEX('계산'!$E$12:$E$761,MATCH("13|10",'계산'!$G$12:$G$761,0)),"")) | T16: =IF(T$6="","",IFERROR(INDEX('계산'!$E$12:$E$761,MATCH("14|10",'계산'!$G$12:$G$761,0)),"")) | U16: =IF(U$6="","",IFERROR(INDEX('계산'!$E$12:$E$761,MATCH("15|10",'계산'!$G$12:$G$761,0)),"")) | V16: =IF(V$6="","",IFERROR(INDEX('계산'!$E$12:$E$761,MATCH("16|10",'계산'!$G$12:$G$761,0)),"")) | W16: =IF(W$6="","",IFERROR(INDEX('계산'!$E$12:$E$761,MATCH("17|10",'계산'!$G$12:$G$761,0)),"")) | X16: =IF(X$6="","",IFERROR(INDEX('계산'!$E$12:$E$761,MATCH("18|10",'계산'!$G$12:$G$761,0)),"")) | Y16: =IF(Y$6="","",IFERROR(INDEX('계산'!$E$12:$E$761,MATCH("19|10",'계산'!$G$12:$G$761,0)),"")) | Z16: =IF(Z$6="","",IFERROR(INDEX('계산'!$E$12:$E$761,MATCH("20|10",'계산'!$G$12:$G$761,0)),"")) | AA16: =IF(AA$6="","",IFERROR(INDEX('계산'!$E$12:$E$761,MATCH("21|10",'계산'!$G$12:$G$761,0)),"")) | AB16: =IF(AB$6="","",IFERROR(INDEX('계산'!$E$12:$E$761,MATCH("22|10",'계산'!$G$12:$G$761,0)),"")) | AC16: =IF(AC$6="","",IFERROR(INDEX('계산'!$E$12:$E$761,MATCH("23|10",'계산'!$G$12:$G$761,0)),"")) | AD16: =IF(AD$6="","",IFERROR(INDEX('계산'!$E$12:$E$761,MATCH("24|10",'계산'!$G$12:$G$761,0)),"")) | AE16: =IF(AE$6="","",IFERROR(INDEX('계산'!$E$12:$E$761,MATCH("25|10",'계산'!$G$12:$G$761,0)),"")) | AF16: =IF(AF$6="","",IFERROR(INDEX('계산'!$E$12:$E$761,MATCH("26|10",'계산'!$G$12:$G$761,0)),"")) | AG16: =IF(AG$6="","",IFERROR(INDEX('계산'!$E$12:$E$761,MATCH("27|10",'계산'!$G$12:$G$761,0)),"")) | AH16: =IF(AH$6="","",IFERROR(INDEX('계산'!$E$12:$E$761,MATCH("28|10",'계산'!$G$12:$G$761,0)),"")) | AI16: =IF(AI$6="","",IFERROR(INDEX('계산'!$E$12:$E$761,MATCH("29|10",'계산'!$G$12:$G$761,0)),"")) | AJ16: =IF(AJ$6="","",IFERROR(INDEX('계산'!$E$12:$E$761,MATCH("30|10",'계산'!$G$12:$G$761,0)),""))
A17: 작업자 | C17: ='계산'!$AN$11 | E17: 11 | G17: =IF(G$6="","",IFERROR(INDEX('계산'!$E$12:$E$761,MATCH("1|11",'계산'!$G$12:$G$761,0)),"")) | H17: =IF(H$6="","",IFERROR(INDEX('계산'!$E$12:$E$761,MATCH("2|11",'계산'!$G$12:$G$761,0)),"")) | I17: =IF(I$6="","",IFERROR(INDEX('계산'!$E$12:$E$761,MATCH("3|11",'계산'!$G$12:$G$761,0)),"")) | J17: =IF(J$6="","",IFERROR(INDEX('계산'!$E$12:$E$761,MATCH("4|11",'계산'!$G$12:$G$761,0)),"")) | K17: =IF(K$6="","",IFERROR(INDEX('계산'!$E$12:$E$761,MATCH("5|11",'계산'!$G$12:$G$761,0)),"")) | L17: =IF(L$6="","",IFERROR(INDEX('계산'!$E$12:$E$761,MATCH("6|11",'계산'!$G$12:$G$761,0)),"")) | M17: =IF(M$6="","",IFERROR(INDEX('계산'!$E$12:$E$761,MATCH("7|11",'계산'!$G$12:$G$761,0)),"")) | N17: =IF(N$6="","",IFERROR(INDEX('계산'!$E$12:$E$761,MATCH("8|11",'계산'!$G$12:$G$761,0)),"")) | O17: =IF(O$6="","",IFERROR(INDEX('계산'!$E$12:$E$761,MATCH("9|11",'계산'!$G$12:$G$761,0)),"")) | P17: =IF(P$6="","",IFERROR(INDEX('계산'!$E$12:$E$761,MATCH("10|11",'계산'!$G$12:$G$761,0)),"")) | Q17: =IF(Q$6="","",IFERROR(INDEX('계산'!$E$12:$E$761,MATCH("11|11",'계산'!$G$12:$G$761,0)),"")) | R17: =IF(R$6="","",IFERROR(INDEX('계산'!$E$12:$E$761,MATCH("12|11",'계산'!$G$12:$G$761,0)),"")) | S17: =IF(S$6="","",IFERROR(INDEX('계산'!$E$12:$E$761,MATCH("13|11",'계산'!$G$12:$G$761,0)),"")) | T17: =IF(T$6="","",IFERROR(INDEX('계산'!$E$12:$E$761,MATCH("14|11",'계산'!$G$12:$G$761,0)),"")) | U17: =IF(U$6="","",IFERROR(INDEX('계산'!$E$12:$E$761,MATCH("15|11",'계산'!$G$12:$G$761,0)),"")) | V17: =IF(V$6="","",IFERROR(INDEX('계산'!$E$12:$E$761,MATCH("16|11",'계산'!$G$12:$G$761,0)),"")) | W17: =IF(W$6="","",IFERROR(INDEX('계산'!$E$12:$E$761,MATCH("17|11",'계산'!$G$12:$G$761,0)),"")) | X17: =IF(X$6="","",IFERROR(INDEX('계산'!$E$12:$E$761,MATCH("18|11",'계산'!$G$12:$G$761,0)),"")) | Y17: =IF(Y$6="","",IFERROR(INDEX('계산'!$E$12:$E$761,MATCH("19|11",'계산'!$G$12:$G$761,0)),"")) | Z17: =IF(Z$6="","",IFERROR(INDEX('계산'!$E$12:$E$761,MATCH("20|11",'계산'!$G$12:$G$761,0)),"")) | AA17: =IF(AA$6="","",IFERROR(INDEX('계산'!$E$12:$E$761,MATCH("21|11",'계산'!$G$12:$G$761,0)),"")) | AB17: =IF(AB$6="","",IFERROR(INDEX('계산'!$E$12:$E$761,MATCH("22|11",'계산'!$G$12:$G$761,0)),"")) | AC17: =IF(AC$6="","",IFERROR(INDEX('계산'!$E$12:$E$761,MATCH("23|11",'계산'!$G$12:$G$761,0)),"")) | AD17: =IF(AD$6="","",IFERROR(INDEX('계산'!$E$12:$E$761,MATCH("24|11",'계산'!$G$12:$G$761,0)),"")) | AE17: =IF(AE$6="","",IFERROR(INDEX('계산'!$E$12:$E$761,MATCH("25|11",'계산'!$G$12:$G$761,0)),"")) | AF17: =IF(AF$6="","",IFERROR(INDEX('계산'!$E$12:$E$761,MATCH("26|11",'계산'!$G$12:$G$761,0)),"")) | AG17: =IF(AG$6="","",IFERROR(INDEX('계산'!$E$12:$E$761,MATCH("27|11",'계산'!$G$12:$G$761,0)),"")) | AH17: =IF(AH$6="","",IFERROR(INDEX('계산'!$E$12:$E$761,MATCH("28|11",'계산'!$G$12:$G$761,0)),"")) | AI17: =IF(AI$6="","",IFERROR(INDEX('계산'!$E$12:$E$761,MATCH("29|11",'계산'!$G$12:$G$761,0)),"")) | AJ17: =IF(AJ$6="","",IFERROR(INDEX('계산'!$E$12:$E$761,MATCH("30|11",'계산'!$G$12:$G$761,0)),""))
E18: 12 | G18: =IF(G$6="","",IFERROR(INDEX('계산'!$E$12:$E$761,MATCH("1|12",'계산'!$G$12:$G$761,0)),"")) | H18: =IF(H$6="","",IFERROR(INDEX('계산'!$E$12:$E$761,MATCH("2|12",'계산'!$G$12:$G$761,0)),"")) | I18: =IF(I$6="","",IFERROR(INDEX('계산'!$E$12:$E$761,MATCH("3|12",'계산'!$G$12:$G$761,0)),"")) | J18: =IF(J$6="","",IFERROR(INDEX('계산'!$E$12:$E$761,MATCH("4|12",'계산'!$G$12:$G$761,0)),"")) | K18: =IF(K$6="","",IFERROR(INDEX('계산'!$E$12:$E$761,MATCH("5|12",'계산'!$G$12:$G$761,0)),"")) | L18: =IF(L$6="","",IFERROR(INDEX('계산'!$E$12:$E$761,MATCH("6|12",'계산'!$G$12:$G$761,0)),"")) | M18: =IF(M$6="","",IFERROR(INDEX('계산'!$E$12:$E$761,MATCH("7|12",'계산'!$G$12:$G$761,0)),"")) | N18: =IF(N$6="","",IFERROR(INDEX('계산'!$E$12:$E$761,MATCH("8|12",'계산'!$G$12:$G$761,0)),"")) | O18: =IF(O$6="","",IFERROR(INDEX('계산'!$E$12:$E$761,MATCH("9|12",'계산'!$G$12:$G$761,0)),"")) | P18: =IF(P$6="","",IFERROR(INDEX('계산'!$E$12:$E$761,MATCH("10|12",'계산'!$G$12:$G$761,0)),"")) | Q18: =IF(Q$6="","",IFERROR(INDEX('계산'!$E$12:$E$761,MATCH("11|12",'계산'!$G$12:$G$761,0)),"")) | R18: =IF(R$6="","",IFERROR(INDEX('계산'!$E$12:$E$761,MATCH("12|12",'계산'!$G$12:$G$761,0)),"")) | S18: =IF(S$6="","",IFERROR(INDEX('계산'!$E$12:$E$761,MATCH("13|12",'계산'!$G$12:$G$761,0)),"")) | T18: =IF(T$6="","",IFERROR(INDEX('계산'!$E$12:$E$761,MATCH("14|12",'계산'!$G$12:$G$761,0)),"")) | U18: =IF(U$6="","",IFERROR(INDEX('계산'!$E$12:$E$761,MATCH("15|12",'계산'!$G$12:$G$761,0)),"")) | V18: =IF(V$6="","",IFERROR(INDEX('계산'!$E$12:$E$761,MATCH("16|12",'계산'!$G$12:$G$761,0)),"")) | W18: =IF(W$6="","",IFERROR(INDEX('계산'!$E$12:$E$761,MATCH("17|12",'계산'!$G$12:$G$761,0)),"")) | X18: =IF(X$6="","",IFERROR(INDEX('계산'!$E$12:$E$761,MATCH("18|12",'계산'!$G$12:$G$761,0)),"")) | Y18: =IF(Y$6="","",IFERROR(INDEX('계산'!$E$12:$E$761,MATCH("19|12",'계산'!$G$12:$G$761,0)),"")) | Z18: =IF(Z$6="","",IFERROR(INDEX('계산'!$E$12:$E$761,MATCH("20|12",'계산'!$G$12:$G$761,0)),"")) | AA18: =IF(AA$6="","",IFERROR(INDEX('계산'!$E$12:$E$761,MATCH("21|12",'계산'!$G$12:$G$761,0)),"")) | AB18: =IF(AB$6="","",IFERROR(INDEX('계산'!$E$12:$E$761,MATCH("22|12",'계산'!$G$12:$G$761,0)),"")) | AC18: =IF(AC$6="","",IFERROR(INDEX('계산'!$E$12:$E$761,MATCH("23|12",'계산'!$G$12:$G$761,0)),"")) | AD18: =IF(AD$6="","",IFERROR(INDEX('계산'!$E$12:$E$761,MATCH("24|12",'계산'!$G$12:$G$761,0)),"")) | AE18: =IF(AE$6="","",IFERROR(INDEX('계산'!$E$12:$E$761,MATCH("25|12",'계산'!$G$12:$G$761,0)),"")) | AF18: =IF(AF$6="","",IFERROR(INDEX('계산'!$E$12:$E$761,MATCH("26|12",'계산'!$G$12:$G$761,0)),"")) | AG18: =IF(AG$6="","",IFERROR(INDEX('계산'!$E$12:$E$761,MATCH("27|12",'계산'!$G$12:$G$761,0)),"")) | AH18: =IF(AH$6="","",IFERROR(INDEX('계산'!$E$12:$E$761,MATCH("28|12",'계산'!$G$12:$G$761,0)),"")) | AI18: =IF(AI$6="","",IFERROR(INDEX('계산'!$E$12:$E$761,MATCH("29|12",'계산'!$G$12:$G$761,0)),"")) | AJ18: =IF(AJ$6="","",IFERROR(INDEX('계산'!$E$12:$E$761,MATCH("30|12",'계산'!$G$12:$G$761,0)),""))
A19: 규 격 | B19: Nominal | C19: =IF(ISNUMBER('계산'!$AO$16),'계산'!$AO$16,IF(AND(ISNUMBER('계산'!$AO$15),ISNUMBER('계산'!$AO$17)),('계산'!$AO$15+'계산'!$AO$17)/2,"")) | E19: 13 | G19: =IF(G$6="","",IFERROR(INDEX('계산'!$E$12:$E$761,MATCH("1|13",'계산'!$G$12:$G$761,0)),"")) | H19: =IF(H$6="","",IFERROR(INDEX('계산'!$E$12:$E$761,MATCH("2|13",'계산'!$G$12:$G$761,0)),"")) | I19: =IF(I$6="","",IFERROR(INDEX('계산'!$E$12:$E$761,MATCH("3|13",'계산'!$G$12:$G$761,0)),"")) | J19: =IF(J$6="","",IFERROR(INDEX('계산'!$E$12:$E$761,MATCH("4|13",'계산'!$G$12:$G$761,0)),"")) | K19: =IF(K$6="","",IFERROR(INDEX('계산'!$E$12:$E$761,MATCH("5|13",'계산'!$G$12:$G$761,0)),"")) | L19: =IF(L$6="","",IFERROR(INDEX('계산'!$E$12:$E$761,MATCH("6|13",'계산'!$G$12:$G$761,0)),"")) | M19: =IF(M$6="","",IFERROR(INDEX('계산'!$E$12:$E$761,MATCH("7|13",'계산'!$G$12:$G$761,0)),"")) | N19: =IF(N$6="","",IFERROR(INDEX('계산'!$E$12:$E$761,MATCH("8|13",'계산'!$G$12:$G$761,0)),"")) | O19: =IF(O$6="","",IFERROR(INDEX('계산'!$E$12:$E$761,MATCH("9|13",'계산'!$G$12:$G$761,0)),"")) | P19: =IF(P$6="","",IFERROR(INDEX('계산'!$E$12:$E$761,MATCH("10|13",'계산'!$G$12:$G$761,0)),"")) | Q19: =IF(Q$6="","",IFERROR(INDEX('계산'!$E$12:$E$761,MATCH("11|13",'계산'!$G$12:$G$761,0)),"")) | R19: =IF(R$6="","",IFERROR(INDEX('계산'!$E$12:$E$761,MATCH("12|13",'계산'!$G$12:$G$761,0)),"")) | S19: =IF(S$6="","",IFERROR(INDEX('계산'!$E$12:$E$761,MATCH("13|13",'계산'!$G$12:$G$761,0)),"")) | T19: =IF(T$6="","",IFERROR(INDEX('계산'!$E$12:$E$761,MATCH("14|13",'계산'!$G$12:$G$761,0)),"")) | U19: =IF(U$6="","",IFERROR(INDEX('계산'!$E$12:$E$761,MATCH("15|13",'계산'!$G$12:$G$761,0)),"")) | V19: =IF(V$6="","",IFERROR(INDEX('계산'!$E$12:$E$761,MATCH("16|13",'계산'!$G$12:$G$761,0)),"")) | W19: =IF(W$6="","",IFERROR(INDEX('계산'!$E$12:$E$761,MATCH("17|13",'계산'!$G$12:$G$761,0)),"")) | X19: =IF(X$6="","",IFERROR(INDEX('계산'!$E$12:$E$761,MATCH("18|13",'계산'!$G$12:$G$761,0)),"")) | Y19: =IF(Y$6="","",IFERROR(INDEX('계산'!$E$12:$E$761,MATCH("19|13",'계산'!$G$12:$G$761,0)),"")) | Z19: =IF(Z$6="","",IFERROR(INDEX('계산'!$E$12:$E$761,MATCH("20|13",'계산'!$G$12:$G$761,0)),"")) | AA19: =IF(AA$6="","",IFERROR(INDEX('계산'!$E$12:$E$761,MATCH("21|13",'계산'!$G$12:$G$761,0)),"")) | AB19: =IF(AB$6="","",IFERROR(INDEX('계산'!$E$12:$E$761,MATCH("22|13",'계산'!$G$12:$G$761,0)),"")) | AC19: =IF(AC$6="","",IFERROR(INDEX('계산'!$E$12:$E$761,MATCH("23|13",'계산'!$G$12:$G$761,0)),"")) | AD19: =IF(AD$6="","",IFERROR(INDEX('계산'!$E$12:$E$761,MATCH("24|13",'계산'!$G$12:$G$761,0)),"")) | AE19: =IF(AE$6="","",IFERROR(INDEX('계산'!$E$12:$E$761,MATCH("25|13",'계산'!$G$12:$G$761,0)),"")) | AF19: =IF(AF$6="","",IFERROR(INDEX('계산'!$E$12:$E$761,MATCH("26|13",'계산'!$G$12:$G$761,0)),"")) | AG19: =IF(AG$6="","",IFERROR(INDEX('계산'!$E$12:$E$761,MATCH("27|13",'계산'!$G$12:$G$761,0)),"")) | AH19: =IF(AH$6="","",IFERROR(INDEX('계산'!$E$12:$E$761,MATCH("28|13",'계산'!$G$12:$G$761,0)),"")) | AI19: =IF(AI$6="","",IFERROR(INDEX('계산'!$E$12:$E$761,MATCH("29|13",'계산'!$G$12:$G$761,0)),"")) | AJ19: =IF(AJ$6="","",IFERROR(INDEX('계산'!$E$12:$E$761,MATCH("30|13",'계산'!$G$12:$G$761,0)),""))
E20: 14 | G20: =IF(G$6="","",IFERROR(INDEX('계산'!$E$12:$E$761,MATCH("1|14",'계산'!$G$12:$G$761,0)),"")) | H20: =IF(H$6="","",IFERROR(INDEX('계산'!$E$12:$E$761,MATCH("2|14",'계산'!$G$12:$G$761,0)),"")) | I20: =IF(I$6="","",IFERROR(INDEX('계산'!$E$12:$E$761,MATCH("3|14",'계산'!$G$12:$G$761,0)),"")) | J20: =IF(J$6="","",IFERROR(INDEX('계산'!$E$12:$E$761,MATCH("4|14",'계산'!$G$12:$G$761,0)),"")) | K20: =IF(K$6="","",IFERROR(INDEX('계산'!$E$12:$E$761,MATCH("5|14",'계산'!$G$12:$G$761,0)),"")) | L20: =IF(L$6="","",IFERROR(INDEX('계산'!$E$12:$E$761,MATCH("6|14",'계산'!$G$12:$G$761,0)),"")) | M20: =IF(M$6="","",IFERROR(INDEX('계산'!$E$12:$E$761,MATCH("7|14",'계산'!$G$12:$G$761,0)),"")) | N20: =IF(N$6="","",IFERROR(INDEX('계산'!$E$12:$E$761,MATCH("8|14",'계산'!$G$12:$G$761,0)),"")) | O20: =IF(O$6="","",IFERROR(INDEX('계산'!$E$12:$E$761,MATCH("9|14",'계산'!$G$12:$G$761,0)),"")) | P20: =IF(P$6="","",IFERROR(INDEX('계산'!$E$12:$E$761,MATCH("10|14",'계산'!$G$12:$G$761,0)),"")) | Q20: =IF(Q$6="","",IFERROR(INDEX('계산'!$E$12:$E$761,MATCH("11|14",'계산'!$G$12:$G$761,0)),"")) | R20: =IF(R$6="","",IFERROR(INDEX('계산'!$E$12:$E$761,MATCH("12|14",'계산'!$G$12:$G$761,0)),"")) | S20: =IF(S$6="","",IFERROR(INDEX('계산'!$E$12:$E$761,MATCH("13|14",'계산'!$G$12:$G$761,0)),"")) | T20: =IF(T$6="","",IFERROR(INDEX('계산'!$E$12:$E$761,MATCH("14|14",'계산'!$G$12:$G$761,0)),"")) | U20: =IF(U$6="","",IFERROR(INDEX('계산'!$E$12:$E$761,MATCH("15|14",'계산'!$G$12:$G$761,0)),"")) | V20: =IF(V$6="","",IFERROR(INDEX('계산'!$E$12:$E$761,MATCH("16|14",'계산'!$G$12:$G$761,0)),"")) | W20: =IF(W$6="","",IFERROR(INDEX('계산'!$E$12:$E$761,MATCH("17|14",'계산'!$G$12:$G$761,0)),"")) | X20: =IF(X$6="","",IFERROR(INDEX('계산'!$E$12:$E$761,MATCH("18|14",'계산'!$G$12:$G$761,0)),"")) | Y20: =IF(Y$6="","",IFERROR(INDEX('계산'!$E$12:$E$761,MATCH("19|14",'계산'!$G$12:$G$761,0)),"")) | Z20: =IF(Z$6="","",IFERROR(INDEX('계산'!$E$12:$E$761,MATCH("20|14",'계산'!$G$12:$G$761,0)),"")) | AA20: =IF(AA$6="","",IFERROR(INDEX('계산'!$E$12:$E$761,MATCH("21|14",'계산'!$G$12:$G$761,0)),"")) | AB20: =IF(AB$6="","",IFERROR(INDEX('계산'!$E$12:$E$761,MATCH("22|14",'계산'!$G$12:$G$761,0)),"")) | AC20: =IF(AC$6="","",IFERROR(INDEX('계산'!$E$12:$E$761,MATCH("23|14",'계산'!$G$12:$G$761,0)),"")) | AD20: =IF(AD$6="","",IFERROR(INDEX('계산'!$E$12:$E$761,MATCH("24|14",'계산'!$G$12:$G$761,0)),"")) | AE20: =IF(AE$6="","",IFERROR(INDEX('계산'!$E$12:$E$761,MATCH("25|14",'계산'!$G$12:$G$761,0)),"")) | AF20: =IF(AF$6="","",IFERROR(INDEX('계산'!$E$12:$E$761,MATCH("26|14",'계산'!$G$12:$G$761,0)),"")) | AG20: =IF(AG$6="","",IFERROR(INDEX('계산'!$E$12:$E$761,MATCH("27|14",'계산'!$G$12:$G$761,0)),"")) | AH20: =IF(AH$6="","",IFERROR(INDEX('계산'!$E$12:$E$761,MATCH("28|14",'계산'!$G$12:$G$761,0)),"")) | AI20: =IF(AI$6="","",IFERROR(INDEX('계산'!$E$12:$E$761,MATCH("29|14",'계산'!$G$12:$G$761,0)),"")) | AJ20: =IF(AJ$6="","",IFERROR(INDEX('계산'!$E$12:$E$761,MATCH("30|14",'계산'!$G$12:$G$761,0)),""))
B21: +Tol(USL) | C21: =IF(AND(ISNUMBER('계산'!$AO$17),ISNUMBER(C19)),'계산'!$AO$17-C19,"") | E21: 15 | G21: =IF(G$6="","",IFERROR(INDEX('계산'!$E$12:$E$761,MATCH("1|15",'계산'!$G$12:$G$761,0)),"")) | H21: =IF(H$6="","",IFERROR(INDEX('계산'!$E$12:$E$761,MATCH("2|15",'계산'!$G$12:$G$761,0)),"")) | I21: =IF(I$6="","",IFERROR(INDEX('계산'!$E$12:$E$761,MATCH("3|15",'계산'!$G$12:$G$761,0)),"")) | J21: =IF(J$6="","",IFERROR(INDEX('계산'!$E$12:$E$761,MATCH("4|15",'계산'!$G$12:$G$761,0)),"")) | K21: =IF(K$6="","",IFERROR(INDEX('계산'!$E$12:$E$761,MATCH("5|15",'계산'!$G$12:$G$761,0)),"")) | L21: =IF(L$6="","",IFERROR(INDEX('계산'!$E$12:$E$761,MATCH("6|15",'계산'!$G$12:$G$761,0)),"")) | M21: =IF(M$6="","",IFERROR(INDEX('계산'!$E$12:$E$761,MATCH("7|15",'계산'!$G$12:$G$761,0)),"")) | N21: =IF(N$6="","",IFERROR(INDEX('계산'!$E$12:$E$761,MATCH("8|15",'계산'!$G$12:$G$761,0)),"")) | O21: =IF(O$6="","",IFERROR(INDEX('계산'!$E$12:$E$761,MATCH("9|15",'계산'!$G$12:$G$761,0)),"")) | P21: =IF(P$6="","",IFERROR(INDEX('계산'!$E$12:$E$761,MATCH("10|15",'계산'!$G$12:$G$761,0)),"")) | Q21: =IF(Q$6="","",IFERROR(INDEX('계산'!$E$12:$E$761,MATCH("11|15",'계산'!$G$12:$G$761,0)),"")) | R21: =IF(R$6="","",IFERROR(INDEX('계산'!$E$12:$E$761,MATCH("12|15",'계산'!$G$12:$G$761,0)),"")) | S21: =IF(S$6="","",IFERROR(INDEX('계산'!$E$12:$E$761,MATCH("13|15",'계산'!$G$12:$G$761,0)),"")) | T21: =IF(T$6="","",IFERROR(INDEX('계산'!$E$12:$E$761,MATCH("14|15",'계산'!$G$12:$G$761,0)),"")) | U21: =IF(U$6="","",IFERROR(INDEX('계산'!$E$12:$E$761,MATCH("15|15",'계산'!$G$12:$G$761,0)),"")) | V21: =IF(V$6="","",IFERROR(INDEX('계산'!$E$12:$E$761,MATCH("16|15",'계산'!$G$12:$G$761,0)),"")) | W21: =IF(W$6="","",IFERROR(INDEX('계산'!$E$12:$E$761,MATCH("17|15",'계산'!$G$12:$G$761,0)),"")) | X21: =IF(X$6="","",IFERROR(INDEX('계산'!$E$12:$E$761,MATCH("18|15",'계산'!$G$12:$G$761,0)),"")) | Y21: =IF(Y$6="","",IFERROR(INDEX('계산'!$E$12:$E$761,MATCH("19|15",'계산'!$G$12:$G$761,0)),"")) | Z21: =IF(Z$6="","",IFERROR(INDEX('계산'!$E$12:$E$761,MATCH("20|15",'계산'!$G$12:$G$761,0)),"")) | AA21: =IF(AA$6="","",IFERROR(INDEX('계산'!$E$12:$E$761,MATCH("21|15",'계산'!$G$12:$G$761,0)),"")) | AB21: =IF(AB$6="","",IFERROR(INDEX('계산'!$E$12:$E$761,MATCH("22|15",'계산'!$G$12:$G$761,0)),"")) | AC21: =IF(AC$6="","",IFERROR(INDEX('계산'!$E$12:$E$761,MATCH("23|15",'계산'!$G$12:$G$761,0)),"")) | AD21: =IF(AD$6="","",IFERROR(INDEX('계산'!$E$12:$E$761,MATCH("24|15",'계산'!$G$12:$G$761,0)),"")) | AE21: =IF(AE$6="","",IFERROR(INDEX('계산'!$E$12:$E$761,MATCH("25|15",'계산'!$G$12:$G$761,0)),"")) | AF21: =IF(AF$6="","",IFERROR(INDEX('계산'!$E$12:$E$761,MATCH("26|15",'계산'!$G$12:$G$761,0)),"")) | AG21: =IF(AG$6="","",IFERROR(INDEX('계산'!$E$12:$E$761,MATCH("27|15",'계산'!$G$12:$G$761,0)),"")) | AH21: =IF(AH$6="","",IFERROR(INDEX('계산'!$E$12:$E$761,MATCH("28|15",'계산'!$G$12:$G$761,0)),"")) | AI21: =IF(AI$6="","",IFERROR(INDEX('계산'!$E$12:$E$761,MATCH("29|15",'계산'!$G$12:$G$761,0)),"")) | AJ21: =IF(AJ$6="","",IFERROR(INDEX('계산'!$E$12:$E$761,MATCH("30|15",'계산'!$G$12:$G$761,0)),""))
E22: 16 | G22: =IF(G$6="","",IFERROR(INDEX('계산'!$E$12:$E$761,MATCH("1|16",'계산'!$G$12:$G$761,0)),"")) | H22: =IF(H$6="","",IFERROR(INDEX('계산'!$E$12:$E$761,MATCH("2|16",'계산'!$G$12:$G$761,0)),"")) | I22: =IF(I$6="","",IFERROR(INDEX('계산'!$E$12:$E$761,MATCH("3|16",'계산'!$G$12:$G$761,0)),"")) | J22: =IF(J$6="","",IFERROR(INDEX('계산'!$E$12:$E$761,MATCH("4|16",'계산'!$G$12:$G$761,0)),"")) | K22: =IF(K$6="","",IFERROR(INDEX('계산'!$E$12:$E$761,MATCH("5|16",'계산'!$G$12:$G$761,0)),"")) | L22: =IF(L$6="","",IFERROR(INDEX('계산'!$E$12:$E$761,MATCH("6|16",'계산'!$G$12:$G$761,0)),"")) | M22: =IF(M$6="","",IFERROR(INDEX('계산'!$E$12:$E$761,MATCH("7|16",'계산'!$G$12:$G$761,0)),"")) | N22: =IF(N$6="","",IFERROR(INDEX('계산'!$E$12:$E$761,MATCH("8|16",'계산'!$G$12:$G$761,0)),"")) | O22: =IF(O$6="","",IFERROR(INDEX('계산'!$E$12:$E$761,MATCH("9|16",'계산'!$G$12:$G$761,0)),"")) | P22: =IF(P$6="","",IFERROR(INDEX('계산'!$E$12:$E$761,MATCH("10|16",'계산'!$G$12:$G$761,0)),"")) | Q22: =IF(Q$6="","",IFERROR(INDEX('계산'!$E$12:$E$761,MATCH("11|16",'계산'!$G$12:$G$761,0)),"")) | R22: =IF(R$6="","",IFERROR(INDEX('계산'!$E$12:$E$761,MATCH("12|16",'계산'!$G$12:$G$761,0)),"")) | S22: =IF(S$6="","",IFERROR(INDEX('계산'!$E$12:$E$761,MATCH("13|16",'계산'!$G$12:$G$761,0)),"")) | T22: =IF(T$6="","",IFERROR(INDEX('계산'!$E$12:$E$761,MATCH("14|16",'계산'!$G$12:$G$761,0)),"")) | U22: =IF(U$6="","",IFERROR(INDEX('계산'!$E$12:$E$761,MATCH("15|16",'계산'!$G$12:$G$761,0)),"")) | V22: =IF(V$6="","",IFERROR(INDEX('계산'!$E$12:$E$761,MATCH("16|16",'계산'!$G$12:$G$761,0)),"")) | W22: =IF(W$6="","",IFERROR(INDEX('계산'!$E$12:$E$761,MATCH("17|16",'계산'!$G$12:$G$761,0)),"")) | X22: =IF(X$6="","",IFERROR(INDEX('계산'!$E$12:$E$761,MATCH("18|16",'계산'!$G$12:$G$761,0)),"")) | Y22: =IF(Y$6="","",IFERROR(INDEX('계산'!$E$12:$E$761,MATCH("19|16",'계산'!$G$12:$G$761,0)),"")) | Z22: =IF(Z$6="","",IFERROR(INDEX('계산'!$E$12:$E$761,MATCH("20|16",'계산'!$G$12:$G$761,0)),"")) | AA22: =IF(AA$6="","",IFERROR(INDEX('계산'!$E$12:$E$761,MATCH("21|16",'계산'!$G$12:$G$761,0)),"")) | AB22: =IF(AB$6="","",IFERROR(INDEX('계산'!$E$12:$E$761,MATCH("22|16",'계산'!$G$12:$G$761,0)),"")) | AC22: =IF(AC$6="","",IFERROR(INDEX('계산'!$E$12:$E$761,MATCH("23|16",'계산'!$G$12:$G$761,0)),"")) | AD22: =IF(AD$6="","",IFERROR(INDEX('계산'!$E$12:$E$761,MATCH("24|16",'계산'!$G$12:$G$761,0)),"")) | AE22: =IF(AE$6="","",IFERROR(INDEX('계산'!$E$12:$E$761,MATCH("25|16",'계산'!$G$12:$G$761,0)),"")) | AF22: =IF(AF$6="","",IFERROR(INDEX('계산'!$E$12:$E$761,MATCH("26|16",'계산'!$G$12:$G$761,0)),"")) | AG22: =IF(AG$6="","",IFERROR(INDEX('계산'!$E$12:$E$761,MATCH("27|16",'계산'!$G$12:$G$761,0)),"")) | AH22: =IF(AH$6="","",IFERROR(INDEX('계산'!$E$12:$E$761,MATCH("28|16",'계산'!$G$12:$G$761,0)),"")) | AI22: =IF(AI$6="","",IFERROR(INDEX('계산'!$E$12:$E$761,MATCH("29|16",'계산'!$G$12:$G$761,0)),"")) | AJ22: =IF(AJ$6="","",IFERROR(INDEX('계산'!$E$12:$E$761,MATCH("30|16",'계산'!$G$12:$G$761,0)),""))
B23: -Tol(LSL) | C23: =IF(AND(ISNUMBER('계산'!$AO$15),ISNUMBER(C19)),C19-'계산'!$AO$15,"") | E23: 17 | G23: =IF(G$6="","",IFERROR(INDEX('계산'!$E$12:$E$761,MATCH("1|17",'계산'!$G$12:$G$761,0)),"")) | H23: =IF(H$6="","",IFERROR(INDEX('계산'!$E$12:$E$761,MATCH("2|17",'계산'!$G$12:$G$761,0)),"")) | I23: =IF(I$6="","",IFERROR(INDEX('계산'!$E$12:$E$761,MATCH("3|17",'계산'!$G$12:$G$761,0)),"")) | J23: =IF(J$6="","",IFERROR(INDEX('계산'!$E$12:$E$761,MATCH("4|17",'계산'!$G$12:$G$761,0)),"")) | K23: =IF(K$6="","",IFERROR(INDEX('계산'!$E$12:$E$761,MATCH("5|17",'계산'!$G$12:$G$761,0)),"")) | L23: =IF(L$6="","",IFERROR(INDEX('계산'!$E$12:$E$761,MATCH("6|17",'계산'!$G$12:$G$761,0)),"")) | M23: =IF(M$6="","",IFERROR(INDEX('계산'!$E$12:$E$761,MATCH("7|17",'계산'!$G$12:$G$761,0)),"")) | N23: =IF(N$6="","",IFERROR(INDEX('계산'!$E$12:$E$761,MATCH("8|17",'계산'!$G$12:$G$761,0)),"")) | O23: =IF(O$6="","",IFERROR(INDEX('계산'!$E$12:$E$761,MATCH("9|17",'계산'!$G$12:$G$761,0)),"")) | P23: =IF(P$6="","",IFERROR(INDEX('계산'!$E$12:$E$761,MATCH("10|17",'계산'!$G$12:$G$761,0)),"")) | Q23: =IF(Q$6="","",IFERROR(INDEX('계산'!$E$12:$E$761,MATCH("11|17",'계산'!$G$12:$G$761,0)),"")) | R23: =IF(R$6="","",IFERROR(INDEX('계산'!$E$12:$E$761,MATCH("12|17",'계산'!$G$12:$G$761,0)),"")) | S23: =IF(S$6="","",IFERROR(INDEX('계산'!$E$12:$E$761,MATCH("13|17",'계산'!$G$12:$G$761,0)),"")) | T23: =IF(T$6="","",IFERROR(INDEX('계산'!$E$12:$E$761,MATCH("14|17",'계산'!$G$12:$G$761,0)),"")) | U23: =IF(U$6="","",IFERROR(INDEX('계산'!$E$12:$E$761,MATCH("15|17",'계산'!$G$12:$G$761,0)),"")) | V23: =IF(V$6="","",IFERROR(INDEX('계산'!$E$12:$E$761,MATCH("16|17",'계산'!$G$12:$G$761,0)),"")) | W23: =IF(W$6="","",IFERROR(INDEX('계산'!$E$12:$E$761,MATCH("17|17",'계산'!$G$12:$G$761,0)),"")) | X23: =IF(X$6="","",IFERROR(INDEX('계산'!$E$12:$E$761,MATCH("18|17",'계산'!$G$12:$G$761,0)),"")) | Y23: =IF(Y$6="","",IFERROR(INDEX('계산'!$E$12:$E$761,MATCH("19|17",'계산'!$G$12:$G$761,0)),"")) | Z23: =IF(Z$6="","",IFERROR(INDEX('계산'!$E$12:$E$761,MATCH("20|17",'계산'!$G$12:$G$761,0)),"")) | AA23: =IF(AA$6="","",IFERROR(INDEX('계산'!$E$12:$E$761,MATCH("21|17",'계산'!$G$12:$G$761,0)),"")) | AB23: =IF(AB$6="","",IFERROR(INDEX('계산'!$E$12:$E$761,MATCH("22|17",'계산'!$G$12:$G$761,0)),"")) | AC23: =IF(AC$6="","",IFERROR(INDEX('계산'!$E$12:$E$761,MATCH("23|17",'계산'!$G$12:$G$761,0)),"")) | AD23: =IF(AD$6="","",IFERROR(INDEX('계산'!$E$12:$E$761,MATCH("24|17",'계산'!$G$12:$G$761,0)),"")) | AE23: =IF(AE$6="","",IFERROR(INDEX('계산'!$E$12:$E$761,MATCH("25|17",'계산'!$G$12:$G$761,0)),"")) | AF23: =IF(AF$6="","",IFERROR(INDEX('계산'!$E$12:$E$761,MATCH("26|17",'계산'!$G$12:$G$761,0)),"")) | AG23: =IF(AG$6="","",IFERROR(INDEX('계산'!$E$12:$E$761,MATCH("27|17",'계산'!$G$12:$G$761,0)),"")) | AH23: =IF(AH$6="","",IFERROR(INDEX('계산'!$E$12:$E$761,MATCH("28|17",'계산'!$G$12:$G$761,0)),"")) | AI23: =IF(AI$6="","",IFERROR(INDEX('계산'!$E$12:$E$761,MATCH("29|17",'계산'!$G$12:$G$761,0)),"")) | AJ23: =IF(AJ$6="","",IFERROR(INDEX('계산'!$E$12:$E$761,MATCH("30|17",'계산'!$G$12:$G$761,0)),""))
E24: 18 | G24: =IF(G$6="","",IFERROR(INDEX('계산'!$E$12:$E$761,MATCH("1|18",'계산'!$G$12:$G$761,0)),"")) | H24: =IF(H$6="","",IFERROR(INDEX('계산'!$E$12:$E$761,MATCH("2|18",'계산'!$G$12:$G$761,0)),"")) | I24: =IF(I$6="","",IFERROR(INDEX('계산'!$E$12:$E$761,MATCH("3|18",'계산'!$G$12:$G$761,0)),"")) | J24: =IF(J$6="","",IFERROR(INDEX('계산'!$E$12:$E$761,MATCH("4|18",'계산'!$G$12:$G$761,0)),"")) | K24: =IF(K$6="","",IFERROR(INDEX('계산'!$E$12:$E$761,MATCH("5|18",'계산'!$G$12:$G$761,0)),"")) | L24: =IF(L$6="","",IFERROR(INDEX('계산'!$E$12:$E$761,MATCH("6|18",'계산'!$G$12:$G$761,0)),"")) | M24: =IF(M$6="","",IFERROR(INDEX('계산'!$E$12:$E$761,MATCH("7|18",'계산'!$G$12:$G$761,0)),"")) | N24: =IF(N$6="","",IFERROR(INDEX('계산'!$E$12:$E$761,MATCH("8|18",'계산'!$G$12:$G$761,0)),"")) | O24: =IF(O$6="","",IFERROR(INDEX('계산'!$E$12:$E$761,MATCH("9|18",'계산'!$G$12:$G$761,0)),"")) | P24: =IF(P$6="","",IFERROR(INDEX('계산'!$E$12:$E$761,MATCH("10|18",'계산'!$G$12:$G$761,0)),"")) | Q24: =IF(Q$6="","",IFERROR(INDEX('계산'!$E$12:$E$761,MATCH("11|18",'계산'!$G$12:$G$761,0)),"")) | R24: =IF(R$6="","",IFERROR(INDEX('계산'!$E$12:$E$761,MATCH("12|18",'계산'!$G$12:$G$761,0)),"")) | S24: =IF(S$6="","",IFERROR(INDEX('계산'!$E$12:$E$761,MATCH("13|18",'계산'!$G$12:$G$761,0)),"")) | T24: =IF(T$6="","",IFERROR(INDEX('계산'!$E$12:$E$761,MATCH("14|18",'계산'!$G$12:$G$761,0)),"")) | U24: =IF(U$6="","",IFERROR(INDEX('계산'!$E$12:$E$761,MATCH("15|18",'계산'!$G$12:$G$761,0)),"")) | V24: =IF(V$6="","",IFERROR(INDEX('계산'!$E$12:$E$761,MATCH("16|18",'계산'!$G$12:$G$761,0)),"")) | W24: =IF(W$6="","",IFERROR(INDEX('계산'!$E$12:$E$761,MATCH("17|18",'계산'!$G$12:$G$761,0)),"")) | X24: =IF(X$6="","",IFERROR(INDEX('계산'!$E$12:$E$761,MATCH("18|18",'계산'!$G$12:$G$761,0)),"")) | Y24: =IF(Y$6="","",IFERROR(INDEX('계산'!$E$12:$E$761,MATCH("19|18",'계산'!$G$12:$G$761,0)),"")) | Z24: =IF(Z$6="","",IFERROR(INDEX('계산'!$E$12:$E$761,MATCH("20|18",'계산'!$G$12:$G$761,0)),"")) | AA24: =IF(AA$6="","",IFERROR(INDEX('계산'!$E$12:$E$761,MATCH("21|18",'계산'!$G$12:$G$761,0)),"")) | AB24: =IF(AB$6="","",IFERROR(INDEX('계산'!$E$12:$E$761,MATCH("22|18",'계산'!$G$12:$G$761,0)),"")) | AC24: =IF(AC$6="","",IFERROR(INDEX('계산'!$E$12:$E$761,MATCH("23|18",'계산'!$G$12:$G$761,0)),"")) | AD24: =IF(AD$6="","",IFERROR(INDEX('계산'!$E$12:$E$761,MATCH("24|18",'계산'!$G$12:$G$761,0)),"")) | AE24: =IF(AE$6="","",IFERROR(INDEX('계산'!$E$12:$E$761,MATCH("25|18",'계산'!$G$12:$G$761,0)),"")) | AF24: =IF(AF$6="","",IFERROR(INDEX('계산'!$E$12:$E$761,MATCH("26|18",'계산'!$G$12:$G$761,0)),"")) | AG24: =IF(AG$6="","",IFERROR(INDEX('계산'!$E$12:$E$761,MATCH("27|18",'계산'!$G$12:$G$761,0)),"")) | AH24: =IF(AH$6="","",IFERROR(INDEX('계산'!$E$12:$E$761,MATCH("28|18",'계산'!$G$12:$G$761,0)),"")) | AI24: =IF(AI$6="","",IFERROR(INDEX('계산'!$E$12:$E$761,MATCH("29|18",'계산'!$G$12:$G$761,0)),"")) | AJ24: =IF(AJ$6="","",IFERROR(INDEX('계산'!$E$12:$E$761,MATCH("30|18",'계산'!$G$12:$G$761,0)),""))
B25: 종 류 | C25: =IF(AND(ISNUMBER('계산'!$AO$15),ISNUMBER('계산'!$AO$17)),"양쪽규격",IF(OR(ISNUMBER('계산'!$AO$15),ISNUMBER('계산'!$AO$17)),"한쪽규격","")) | E25: 19 | G25: =IF(G$6="","",IFERROR(INDEX('계산'!$E$12:$E$761,MATCH("1|19",'계산'!$G$12:$G$761,0)),"")) | H25: =IF(H$6="","",IFERROR(INDEX('계산'!$E$12:$E$761,MATCH("2|19",'계산'!$G$12:$G$761,0)),"")) | I25: =IF(I$6="","",IFERROR(INDEX('계산'!$E$12:$E$761,MATCH("3|19",'계산'!$G$12:$G$761,0)),"")) | J25: =IF(J$6="","",IFERROR(INDEX('계산'!$E$12:$E$761,MATCH("4|19",'계산'!$G$12:$G$761,0)),"")) | K25: =IF(K$6="","",IFERROR(INDEX('계산'!$E$12:$E$761,MATCH("5|19",'계산'!$G$12:$G$761,0)),"")) | L25: =IF(L$6="","",IFERROR(INDEX('계산'!$E$12:$E$761,MATCH("6|19",'계산'!$G$12:$G$761,0)),"")) | M25: =IF(M$6="","",IFERROR(INDEX('계산'!$E$12:$E$761,MATCH("7|19",'계산'!$G$12:$G$761,0)),"")) | N25: =IF(N$6="","",IFERROR(INDEX('계산'!$E$12:$E$761,MATCH("8|19",'계산'!$G$12:$G$761,0)),"")) | O25: =IF(O$6="","",IFERROR(INDEX('계산'!$E$12:$E$761,MATCH("9|19",'계산'!$G$12:$G$761,0)),"")) | P25: =IF(P$6="","",IFERROR(INDEX('계산'!$E$12:$E$761,MATCH("10|19",'계산'!$G$12:$G$761,0)),"")) | Q25: =IF(Q$6="","",IFERROR(INDEX('계산'!$E$12:$E$761,MATCH("11|19",'계산'!$G$12:$G$761,0)),"")) | R25: =IF(R$6="","",IFERROR(INDEX('계산'!$E$12:$E$761,MATCH("12|19",'계산'!$G$12:$G$761,0)),"")) | S25: =IF(S$6="","",IFERROR(INDEX('계산'!$E$12:$E$761,MATCH("13|19",'계산'!$G$12:$G$761,0)),"")) | T25: =IF(T$6="","",IFERROR(INDEX('계산'!$E$12:$E$761,MATCH("14|19",'계산'!$G$12:$G$761,0)),"")) | U25: =IF(U$6="","",IFERROR(INDEX('계산'!$E$12:$E$761,MATCH("15|19",'계산'!$G$12:$G$761,0)),"")) | V25: =IF(V$6="","",IFERROR(INDEX('계산'!$E$12:$E$761,MATCH("16|19",'계산'!$G$12:$G$761,0)),"")) | W25: =IF(W$6="","",IFERROR(INDEX('계산'!$E$12:$E$761,MATCH("17|19",'계산'!$G$12:$G$761,0)),"")) | X25: =IF(X$6="","",IFERROR(INDEX('계산'!$E$12:$E$761,MATCH("18|19",'계산'!$G$12:$G$761,0)),"")) | Y25: =IF(Y$6="","",IFERROR(INDEX('계산'!$E$12:$E$761,MATCH("19|19",'계산'!$G$12:$G$761,0)),"")) | Z25: =IF(Z$6="","",IFERROR(INDEX('계산'!$E$12:$E$761,MATCH("20|19",'계산'!$G$12:$G$761,0)),"")) | AA25: =IF(AA$6="","",IFERROR(INDEX('계산'!$E$12:$E$761,MATCH("21|19",'계산'!$G$12:$G$761,0)),"")) | AB25: =IF(AB$6="","",IFERROR(INDEX('계산'!$E$12:$E$761,MATCH("22|19",'계산'!$G$12:$G$761,0)),"")) | AC25: =IF(AC$6="","",IFERROR(INDEX('계산'!$E$12:$E$761,MATCH("23|19",'계산'!$G$12:$G$761,0)),"")) | AD25: =IF(AD$6="","",IFERROR(INDEX('계산'!$E$12:$E$761,MATCH("24|19",'계산'!$G$12:$G$761,0)),"")) | AE25: =IF(AE$6="","",IFERROR(INDEX('계산'!$E$12:$E$761,MATCH("25|19",'계산'!$G$12:$G$761,0)),"")) | AF25: =IF(AF$6="","",IFERROR(INDEX('계산'!$E$12:$E$761,MATCH("26|19",'계산'!$G$12:$G$761,0)),"")) | AG25: =IF(AG$6="","",IFERROR(INDEX('계산'!$E$12:$E$761,MATCH("27|19",'계산'!$G$12:$G$761,0)),"")) | AH25: =IF(AH$6="","",IFERROR(INDEX('계산'!$E$12:$E$761,MATCH("28|19",'계산'!$G$12:$G$761,0)),"")) | AI25: =IF(AI$6="","",IFERROR(INDEX('계산'!$E$12:$E$761,MATCH("29|19",'계산'!$G$12:$G$761,0)),"")) | AJ25: =IF(AJ$6="","",IFERROR(INDEX('계산'!$E$12:$E$761,MATCH("30|19",'계산'!$G$12:$G$761,0)),""))
E26: 20 | G26: =IF(G$6="","",IFERROR(INDEX('계산'!$E$12:$E$761,MATCH("1|20",'계산'!$G$12:$G$761,0)),"")) | H26: =IF(H$6="","",IFERROR(INDEX('계산'!$E$12:$E$761,MATCH("2|20",'계산'!$G$12:$G$761,0)),"")) | I26: =IF(I$6="","",IFERROR(INDEX('계산'!$E$12:$E$761,MATCH("3|20",'계산'!$G$12:$G$761,0)),"")) | J26: =IF(J$6="","",IFERROR(INDEX('계산'!$E$12:$E$761,MATCH("4|20",'계산'!$G$12:$G$761,0)),"")) | K26: =IF(K$6="","",IFERROR(INDEX('계산'!$E$12:$E$761,MATCH("5|20",'계산'!$G$12:$G$761,0)),"")) | L26: =IF(L$6="","",IFERROR(INDEX('계산'!$E$12:$E$761,MATCH("6|20",'계산'!$G$12:$G$761,0)),"")) | M26: =IF(M$6="","",IFERROR(INDEX('계산'!$E$12:$E$761,MATCH("7|20",'계산'!$G$12:$G$761,0)),"")) | N26: =IF(N$6="","",IFERROR(INDEX('계산'!$E$12:$E$761,MATCH("8|20",'계산'!$G$12:$G$761,0)),"")) | O26: =IF(O$6="","",IFERROR(INDEX('계산'!$E$12:$E$761,MATCH("9|20",'계산'!$G$12:$G$761,0)),"")) | P26: =IF(P$6="","",IFERROR(INDEX('계산'!$E$12:$E$761,MATCH("10|20",'계산'!$G$12:$G$761,0)),"")) | Q26: =IF(Q$6="","",IFERROR(INDEX('계산'!$E$12:$E$761,MATCH("11|20",'계산'!$G$12:$G$761,0)),"")) | R26: =IF(R$6="","",IFERROR(INDEX('계산'!$E$12:$E$761,MATCH("12|20",'계산'!$G$12:$G$761,0)),"")) | S26: =IF(S$6="","",IFERROR(INDEX('계산'!$E$12:$E$761,MATCH("13|20",'계산'!$G$12:$G$761,0)),"")) | T26: =IF(T$6="","",IFERROR(INDEX('계산'!$E$12:$E$761,MATCH("14|20",'계산'!$G$12:$G$761,0)),"")) | U26: =IF(U$6="","",IFERROR(INDEX('계산'!$E$12:$E$761,MATCH("15|20",'계산'!$G$12:$G$761,0)),"")) | V26: =IF(V$6="","",IFERROR(INDEX('계산'!$E$12:$E$761,MATCH("16|20",'계산'!$G$12:$G$761,0)),"")) | W26: =IF(W$6="","",IFERROR(INDEX('계산'!$E$12:$E$761,MATCH("17|20",'계산'!$G$12:$G$761,0)),"")) | X26: =IF(X$6="","",IFERROR(INDEX('계산'!$E$12:$E$761,MATCH("18|20",'계산'!$G$12:$G$761,0)),"")) | Y26: =IF(Y$6="","",IFERROR(INDEX('계산'!$E$12:$E$761,MATCH("19|20",'계산'!$G$12:$G$761,0)),"")) | Z26: =IF(Z$6="","",IFERROR(INDEX('계산'!$E$12:$E$761,MATCH("20|20",'계산'!$G$12:$G$761,0)),"")) | AA26: =IF(AA$6="","",IFERROR(INDEX('계산'!$E$12:$E$761,MATCH("21|20",'계산'!$G$12:$G$761,0)),"")) | AB26: =IF(AB$6="","",IFERROR(INDEX('계산'!$E$12:$E$761,MATCH("22|20",'계산'!$G$12:$G$761,0)),"")) | AC26: =IF(AC$6="","",IFERROR(INDEX('계산'!$E$12:$E$761,MATCH("23|20",'계산'!$G$12:$G$761,0)),"")) | AD26: =IF(AD$6="","",IFERROR(INDEX('계산'!$E$12:$E$761,MATCH("24|20",'계산'!$G$12:$G$761,0)),"")) | AE26: =IF(AE$6="","",IFERROR(INDEX('계산'!$E$12:$E$761,MATCH("25|20",'계산'!$G$12:$G$761,0)),"")) | AF26: =IF(AF$6="","",IFERROR(INDEX('계산'!$E$12:$E$761,MATCH("26|20",'계산'!$G$12:$G$761,0)),"")) | AG26: =IF(AG$6="","",IFERROR(INDEX('계산'!$E$12:$E$761,MATCH("27|20",'계산'!$G$12:$G$761,0)),"")) | AH26: =IF(AH$6="","",IFERROR(INDEX('계산'!$E$12:$E$761,MATCH("28|20",'계산'!$G$12:$G$761,0)),"")) | AI26: =IF(AI$6="","",IFERROR(INDEX('계산'!$E$12:$E$761,MATCH("29|20",'계산'!$G$12:$G$761,0)),"")) | AJ26: =IF(AJ$6="","",IFERROR(INDEX('계산'!$E$12:$E$761,MATCH("30|20",'계산'!$G$12:$G$761,0)),""))
E27: 평균(X) | G27: =IF(G$6="","",'계산'!$M$2) | H27: =IF(H$6="","",'계산'!$M$3) | I27: =IF(I$6="","",'계산'!$M$4) | J27: =IF(J$6="","",'계산'!$M$5) | K27: =IF(K$6="","",'계산'!$M$6) | L27: =IF(L$6="","",'계산'!$M$7) | M27: =IF(M$6="","",'계산'!$M$8) | N27: =IF(N$6="","",'계산'!$M$9) | O27: =IF(O$6="","",'계산'!$M$10) | P27: =IF(P$6="","",'계산'!$M$11) | Q27: =IF(Q$6="","",'계산'!$M$12) | R27: =IF(R$6="","",'계산'!$M$13) | S27: =IF(S$6="","",'계산'!$M$14) | T27: =IF(T$6="","",'계산'!$M$15) | U27: =IF(U$6="","",'계산'!$M$16) | V27: =IF(V$6="","",'계산'!$M$17) | W27: =IF(W$6="","",'계산'!$M$18) | X27: =IF(X$6="","",'계산'!$M$19) | Y27: =IF(Y$6="","",'계산'!$M$20) | Z27: =IF(Z$6="","",'계산'!$M$21) | AA27: =IF(AA$6="","",'계산'!$M$22) | AB27: =IF(AB$6="","",'계산'!$M$23) | AC27: =IF(AC$6="","",'계산'!$M$24) | AD27: =IF(AD$6="","",'계산'!$M$25) | AE27: =IF(AE$6="","",'계산'!$M$26) | AF27: =IF(AF$6="","",'계산'!$M$27) | AG27: =IF(AG$6="","",'계산'!$M$28) | AH27: =IF(AH$6="","",'계산'!$M$29) | AI27: =IF(AI$6="","",'계산'!$M$30) | AJ27: =IF(AJ$6="","",'계산'!$M$31)
